Workbook

Sheet Inputs
A1: Cost of Hydrogen From Electrolysis: Input Data
A2: Study | B2: User Inputs | C2: Princeton ZERO Lab | D2: Electric Hydrogen | E2: Energy Innovation LLC | F2: Clean Energy Developer 1 | G2: Clean Energy Developer 2 | H2: Rhodium Group | I2: Wood Mackenzie | J2: Energy Futures Initiative | K2: E3/ACORE | L2: MIT Energy Initiative
A3: Electrolysis Facility Fixed Cost Assumptions
A4: Electrolyzer Facility Cost (/kW) | B4: 1150 | C4: 1200 | D4: 800 | E4: 1400 | F4: 927 | G4: 1500 | H4: 1500 | I4: 2210 | J4: 670 | K4: 1500 | L4: 1189
A5: Electrolysis Efficiency (kWe/kgH2) | B5: 50 | C5: 50 | D5: 52.86 | E5: 50 | F5: 55.15 | G5: 50 | H5: 55.5 | I5: 53.97 | J5: 50 | K5: 56.27 | L5: 54.3
A6: Project Financial Lifetime (Years)¹ | B6: 10 | C6: 10 | D6: 20 | E6: 10 | F6: 25 | G6: 20 | H6: 20 | I6: 10 | J6: 10 | K6: 10 | L6: 20
A7: Cost of Capital (WACC, real) | B7: 0.08 | C7: 0.08 | D7: 0.08 | E7: 0.07 | F7: 0.08 | G7: 0.085 | H7: 0.064 | I7: 0.08 | J7: 0.025 | K7: 0.08 | L7: 0.04
A8: Fixed O&M (% CAPEX /kW-yr) | B8: 0.025 | C8: 0.05 | D8: 0 | E8: 0.064 | F8: 0.011 | G8: 0.03 | H8: 0.02 | I8: 0.035 | J8: 0.065 | K8: 0.053 | L8: 0.0148
A9: Other Fixed Costs (/kW-yr) | B9: 0 | C9: 85 | D9: 25 | E9: 0 | F9: 0 | G9: =-PMT(G7,G6,G4*0.3/(1+G7)^10) -> 21.031529 | H9: 0 | I9: 0 | J9: 0 | K9: 8.2 | L9: 20.62
A10: Description of other fixed costs | C10: Grid interconnection cost. Intentionally conservative, using Los Angeles rates as a reference. | D10: n/a | E10: Financing and Tax Shield.³ | G10: - Stack replacement after 10y for 30% of initial project CAPEX - If sourcing is made through PPA, basis risk (depending on PPA contract) and retail electricity fees should be added to cost of electricity | H10: n/a | I10: Financing and Tax Shield.³ | J10: n/a | K10: Grid interconnection cost. | L10: Cost of above-ground hydrogen storage needed to ensure a constant hydrogen delivery rate.
A11: Sum of Annual Fixed Costs (/kW-yr) | B11: =-PMT(B7,B6,B4)+B8*B4+B9 -> 200.13391 | C11: =-PMT(C7,C6,C4)+C8*C4+C9 -> 323.83539 | D11: =-PMT(D7,D6,D4)+D8*D4+D9 -> 106.48177 | E11: =-PMT(E7,E6,E4)+E8*E4+E9 -> 288.9285 | F11: =-PMT(F7,F6,F4)+F8*F4+F9 -> 97.037228 | G11: =-PMT(G7,G6,G4)+G8*G4+G9 -> 224.53799 | H11: =-PMT(H7,H6,H4)+H8*H4+H9 -> 165.05519 | I11: =-PMT(I7,I6,I4)+I8*I4+I9 -> 406.70517 | J11: 120.33 | K11: =-PMT(K7,K6,K4)+K8*K4+K9 -> 311.24423 | L11: =-PMT(L7,L6,L4)+L8*L4+L9 -> 125.7059
A12: Electricity Cost and Availability Assumptions
A13: Average Electricity Cost ($/MWh) | B13: 30 | C13: 24-41 | D13: 25 | E13: 16-27 | F13: 18-24 | G13: 30, 50, 45 | H13: 23, 31 | I13: 34, 32 | J13: 26 | K13: not enough information⁴ | L13: 41, 27
A14: Electrolyzer Utilization Rate (%) | B14: 0.7 | C14: 71-97 | D14: 70 | E14: 82-88 | F14: 70-80 | G14: 35, 56, 70 | H14: 26, 25 | I14: 46, 72 | J14: 40 | K14: not enough information⁴ | L14: 81, 83
A15: Location | B15: - | C15: Western US | D15: Texas, Oklahoma | E15: Texas, Minnesota | F15: Texas | G15: n/a | H15: n/a | I15: Arizona, Texas | J15: Texas | K15: Eastern US | L15: Florida, Texas
A16: Available Resources | B16: - | C16: Regional Variation | D16: Wind and Solar | E16: Wind and Solar | F16: Wind and Solar | G16: Solar Only, Wind Only, Wind and Solar | H16: Solar Only, Solar and Storage | I16: Solar Only, Wind and Solar | J16: Wind Only | K16: Solar Only, Wind Only, Wind and Solar | L16: Wind and Solar
A17: Allowed Oversizing of Clean Generation? | B17: - | C17: Yes | D17: Yes | E17: Yes | F17: Yes | G17: Yes | H17: No | I17: Yes | J17: No | K17: n/a | L17: Yes
A18: Allowed Sales of Excess Clean Power? | B18: - | C18: Yes | D18: Yes | E18: Yes | F18: Yes | G18: No | H18: No | I18: No | J18: No | K18: n/a | L18: Yes
A19: Calculated LCOH (post-subsidy): | B19: =((B11/(B14*8760)+B13/1000)*B5-PMT(B7,B6,PV(B7,10,B22)))/(1-B23) -> 0.13188121
A21: Other Parameters | D21: Color Key | G21: Links to Public Studies
A22: Tax Credit Value | B22: 3 | D22: Input Field | E22: Known Value | G22: Princeton ZERO Lab | H22: Energy Futures Initiative
A23: Effective Tax Rate | B23: 0 | D23: Output Field | E23: Calculated Value | G23: Energy Innovation LLC | H23: E3/ACORE
A24: Hydrogen Target Cost | B24: 1.25 | D24: Other Field | E24: Assumed Value | G24: Rhodium Group | H24: MIT Energy Initiative
G25: Wood Mackenzie
F59: Note: Filled markers indicate studies that allowed both oversizing of clean generating capacity and sales of excess clean generation. Patterned markers indicate studies that allowed oversizing but not excess sales. Unfilled markers indicate studies that assumed clean generating capacity to be equal to electrolyzer capacity.

Sheet Results
A1: LCOH Outputs
A2: Chosen Fixed Costs: | B2: User Inputs
A3: Avg. Electricity Cost ($/MWh) | B3: 0 | C3: 10 | D3: 20 | E3: 30 | F3: 40 | G3: 50 | H3: 60
A4: Electrolyzer Utilization Rate | B4: "Gate" Cost per kg of Hydrogen (post-subsidy)
A5: 0.1 | B5: =((HLOOKUP(Results!$B$2,Inputs!$B$2:$L$11,10,FALSE)/($A5*8760)+B$3/1000)*HLOOKUP(Results!$B$2,Inputs!$B$2:'Inputs'!$L$9,4,FALSE) - PMT(HLOOKUP(Results!$B$2,Inputs!$B$2:'Inputs'!$L$9,6,FALSE),HLOOKUP(Results!$B$2,Inputs!$B$2:'Inputs'!$L$9,5,FALSE),PV(HLOOKUP(Results!$B$2,Inputs!$B$2:'Inputs'!$L$9,6,FALSE),10,Inputs!$B$22)))/(1-Inputs!$B$23) -> 8.4231685 | C5: =((HLOOKUP(Results!$B$2,Inputs!$B$2:$L$11,10,FALSE)/($A5*8760)+C$3/1000)*HLOOKUP(Results!$B$2,Inputs!$B$2:'Inputs'!$L$9,4,FALSE) - PMT(HLOOKUP(Results!$B$2,Inputs!$B$2:'Inputs'!$L$9,6,FALSE),HLOOKUP(Results!$B$2,Inputs!$B$2:'Inputs'!$L$9,5,FALSE),PV(HLOOKUP(Results!$B$2,Inputs!$B$2:'Inputs'!$L$9,6,FALSE),10,Inputs!$B$22)))/(1-Inputs!$B$23) -> 8.9231685 | D5: =((HLOOKUP(Results!$B$2,Inputs!$B$2:$L$11,10,FALSE)/($A5*8760)+D$3/1000)*HLOOKUP(Results!$B$2,Inputs!$B$2:'Inputs'!$L$9,4,FALSE) - PMT(HLOOKUP(Results!$B$2,Inputs!$B$2:'Inputs'!$L$9,6,FALSE),HLOOKUP(Results!$B$2,Inputs!$B$2:'Inputs'!$L$9,5,FALSE),PV(HLOOKUP(Results!$B$2,Inputs!$B$2:'Inputs'!$L$9,6,FALSE),10,Inputs!$B$22)))/(1-Inputs!$B$23) -> 9.4231685 | E5: =((HLOOKUP(Results!$B$2,Inputs!$B$2:$L$11,10,FALSE)/($A5*8760)+E$3/1000)*HLOOKUP(Results!$B$2,Inputs!$B$2:'Inputs'!$L$9,4,FALSE) - PMT(HLOOKUP(Results!$B$2,Inputs!$B$2:'Inputs'!$L$9,6,FALSE),HLOOKUP(Results!$B$2,Inputs!$B$2:'Inputs'!$L$9,5,FALSE),PV(HLOOKUP(Results!$B$2,Inputs!$B$2:'Inputs'!$L$9,6,FALSE),10,Inputs!$B$22)))/(1-Inputs!$B$23) -> 9.9231685 | F5: =((HLOOKUP(Results!$B$2,Inputs!$B$2:$L$11,10,FALSE)/($A5*8760)+F$3/1000)*HLOOKUP(Results!$B$2,Inputs!$B$2:'Inputs'!$L$9,4,FALSE) - PMT(HLOOKUP(Results!$B$2,Inputs!$B$2:'Inputs'!$L$9,6,FALSE),HLOOKUP(Results!$B$2,Inputs!$B$2:'Inputs'!$L$9,5,FALSE),PV(HLOOKUP(Results!$B$2,Inputs!$B$2:'Inputs'!$L$9,6,FALSE),10,Inputs!$B$22)))/(1-Inputs!$B$23) -> 10.423168 | G5: =((HLOOKUP(Results!$B$2,Inputs!$B$2:$L$11,10,FALSE)/($A5*8760)+G$3/1000)*HLOOKUP(Results!$B$2,Inputs!$B$2:'Inputs'!$L$9,4,FALSE) - PMT(HLOOKUP(Results!$B$2,Inputs!$B$2:'Inputs'!$L$9,6,FALSE),HLOOKUP(Results!$B$2,Inputs!$B$2:'Inputs'!$L$9,5,FALSE),PV(HLOOKUP(Results!$B$2,Inputs!$B$2:'Inputs'!$L$9,6,FALSE),10,Inputs!$B$22)))/(1-Inputs!$B$23) -> 10.923168 | H5: =((HLOOKUP(Results!$B$2,Inputs!$B$2:$L$11,10,FALSE)/($A5*8760)+H$3/1000)*HLOOKUP(Results!$B$2,Inputs!$B$2:'Inputs'!$L$9,4,FALSE) - PMT(HLOOKUP(Results!$B$2,Inputs!$B$2:'Inputs'!$L$9,6,FALSE),HLOOKUP(Results!$B$2,Inputs!$B$2:'Inputs'!$L$9,5,FALSE),PV(HLOOKUP(Results!$B$2,Inputs!$B$2:'Inputs'!$L$9,6,FALSE),10,Inputs!$B$22)))/(1-Inputs!$B$23) -> 11.423168
A6: 0.2 | B6: =((HLOOKUP(Results!$B$2,Inputs!$B$2:$L$11,10,FALSE)/($A6*8760)+B$3/1000)*HLOOKUP(Results!$B$2,Inputs!$B$2:'Inputs'!$L$9,4,FALSE) - PMT(HLOOKUP(Results!$B$2,Inputs!$B$2:'Inputs'!$L$9,6,FALSE),HLOOKUP(Results!$B$2,Inputs!$B$2:'Inputs'!$L$9,5,FALSE),PV(HLOOKUP(Results!$B$2,Inputs!$B$2:'Inputs'!$L$9,6,FALSE),10,Inputs!$B$22)))/(1-Inputs!$B$23) -> 2.7115842 | C6: =((HLOOKUP(Results!$B$2,Inputs!$B$2:$L$11,10,FALSE)/($A6*8760)+C$3/1000)*HLOOKUP(Results!$B$2,Inputs!$B$2:'Inputs'!$L$9,4,FALSE) - PMT(HLOOKUP(Results!$B$2,Inputs!$B$2:'Inputs'!$L$9,6,FALSE),HLOOKUP(Results!$B$2,Inputs!$B$2:'Inputs'!$L$9,5,FALSE),PV(HLOOKUP(Results!$B$2,Inputs!$B$2:'Inputs'!$L$9,6,FALSE),10,Inputs!$B$22)))/(1-Inputs!$B$23) -> 3.2115842 | D6: =((HLOOKUP(Results!$B$2,Inputs!$B$2:$L$11,10,FALSE)/($A6*8760)+D$3/1000)*HLOOKUP(Results!$B$2,Inputs!$B$2:'Inputs'!$L$9,4,FALSE) - PMT(HLOOKUP(Results!$B$2,Inputs!$B$2:'Inputs'!$L$9,6,FALSE),HLOOKUP(Results!$B$2,Inputs!$B$2:'Inputs'!$L$9,5,FALSE),PV(HLOOKUP(Results!$B$2,Inputs!$B$2:'Inputs'!$L$9,6,FALSE),10,Inputs!$B$22)))/(1-Inputs!$B$23) -> 3.7115842 | E6: =((HLOOKUP(Results!$B$2,Inputs!$B$2:$L$11,10,FALSE)/($A6*8760)+E$3/1000)*HLOOKUP(Results!$B$2,Inputs!$B$2:'Inputs'!$L$9,4,FALSE) - PMT(HLOOKUP(Results!$B$2,Inputs!$B$2:'Inputs'!$L$9,6,FALSE),HLOOKUP(Results!$B$2,Inputs!$B$2:'Inputs'!$L$9,5,FALSE),PV(HLOOKUP(Results!$B$2,Inputs!$B$2:'Inputs'!$L$9,6,FALSE),10,Inputs!$B$22)))/(1-Inputs!$B$23) -> 4.2115842 | F6: =((HLOOKUP(Results!$B$2,Inputs!$B$2:$L$11,10,FALSE)/($A6*8760)+F$3/1000)*HLOOKUP(Results!$B$2,Inputs!$B$2:'Inputs'!$L$9,4,FALSE) - PMT(HLOOKUP(Results!$B$2,Inputs!$B$2:'Inputs'!$L$9,6,FALSE),HLOOKUP(Results!$B$2,Inputs!$B$2:'Inputs'!$L$9,5,FALSE),PV(HLOOKUP(Results!$B$2,Inputs!$B$2:'Inputs'!$L$9,6,FALSE),10,Inputs!$B$22)))/(1-Inputs!$B$23) -> 4.7115842 | G6: =((HLOOKUP(Results!$B$2,Inputs!$B$2:$L$11,10,FALSE)/($A6*8760)+G$3/1000)*HLOOKUP(Results!$B$2,Inputs!$B$2:'Inputs'!$L$9,4,FALSE) - PMT(HLOOKUP(Results!$B$2,Inputs!$B$2:'Inputs'!$L$9,6,FALSE),HLOOKUP(Results!$B$2,Inputs!$B$2:'Inputs'!$L$9,5,FALSE),PV(HLOOKUP(Results!$B$2,Inputs!$B$2:'Inputs'!$L$9,6,FALSE),10,Inputs!$B$22)))/(1-Inputs!$B$23) -> 5.2115842 | H6: =((HLOOKUP(Results!$B$2,Inputs!$B$2:$L$11,10,FALSE)/($A6*8760)+H$3/1000)*HLOOKUP(Results!$B$2,Inputs!$B$2:'Inputs'!$L$9,4,FALSE) - PMT(HLOOKUP(Results!$B$2,Inputs!$B$2:'Inputs'!$L$9,6,FALSE),HLOOKUP(Results!$B$2,Inputs!$B$2:'Inputs'!$L$9,5,FALSE),PV(HLOOKUP(Results!$B$2,Inputs!$B$2:'Inputs'!$L$9,6,FALSE),10,Inputs!$B$22)))/(1-Inputs!$B$23) -> 5.7115842
A7: 0.3 | B7: =((HLOOKUP(Results!$B$2,Inputs!$B$2:$L$11,10,FALSE)/($A7*8760)+B$3/1000)*HLOOKUP(Results!$B$2,Inputs!$B$2:'Inputs'!$L$9,4,FALSE) - PMT(HLOOKUP(Results!$B$2,Inputs!$B$2:'Inputs'!$L$9,6,FALSE),HLOOKUP(Results!$B$2,Inputs!$B$2:'Inputs'!$L$9,5,FALSE),PV(HLOOKUP(Results!$B$2,Inputs!$B$2:'Inputs'!$L$9,6,FALSE),10,Inputs!$B$22)))/(1-Inputs!$B$23) -> 0.80772283 | C7: =((HLOOKUP(Results!$B$2,Inputs!$B$2:$L$11,10,FALSE)/($A7*8760)+C$3/1000)*HLOOKUP(Results!$B$2,Inputs!$B$2:'Inputs'!$L$9,4,FALSE) - PMT(HLOOKUP(Results!$B$2,Inputs!$B$2:'Inputs'!$L$9,6,FALSE),HLOOKUP(Results!$B$2,Inputs!$B$2:'Inputs'!$L$9,5,FALSE),PV(HLOOKUP(Results!$B$2,Inputs!$B$2:'Inputs'!$L$9,6,FALSE),10,Inputs!$B$22)))/(1-Inputs!$B$23) -> 1.3077228 | D7: =((HLOOKUP(Results!$B$2,Inputs!$B$2:$L$11,10,FALSE)/($A7*8760)+D$3/1000)*HLOOKUP(Results!$B$2,Inputs!$B$2:'Inputs'!$L$9,4,FALSE) - PMT(HLOOKUP(Results!$B$2,Inputs!$B$2:'Inputs'!$L$9,6,FALSE),HLOOKUP(Results!$B$2,Inputs!$B$2:'Inputs'!$L$9,5,FALSE),PV(HLOOKUP(Results!$B$2,Inputs!$B$2:'Inputs'!$L$9,6,FALSE),10,Inputs!$B$22)))/(1-Inputs!$B$23) -> 1.8077228 | E7: =((HLOOKUP(Results!$B$2,Inputs!$B$2:$L$11,10,FALSE)/($A7*8760)+E$3/1000)*HLOOKUP(Results!$B$2,Inputs!$B$2:'Inputs'!$L$9,4,FALSE) - PMT(HLOOKUP(Results!$B$2,Inputs!$B$2:'Inputs'!$L$9,6,FALSE),HLOOKUP(Results!$B$2,Inputs!$B$2:'Inputs'!$L$9,5,FALSE),PV(HLOOKUP(Results!$B$2,Inputs!$B$2:'Inputs'!$L$9,6,FALSE),10,Inputs!$B$22)))/(1-Inputs!$B$23) -> 2.3077228 | F7: =((HLOOKUP(Results!$B$2,Inputs!$B$2:$L$11,10,FALSE)/($A7*8760)+F$3/1000)*HLOOKUP(Results!$B$2,Inputs!$B$2:'Inputs'!$L$9,4,FALSE) - PMT(HLOOKUP(Results!$B$2,Inputs!$B$2:'Inputs'!$L$9,6,FALSE),HLOOKUP(Results!$B$2,Inputs!$B$2:'Inputs'!$L$9,5,FALSE),PV(HLOOKUP(Results!$B$2,Inputs!$B$2:'Inputs'!$L$9,6,FALSE),10,Inputs!$B$22)))/(1-Inputs!$B$23) -> 2.8077228 | G7: =((HLOOKUP(Results!$B$2,Inputs!$B$2:$L$11,10,FALSE)/($A7*8760)+G$3/1000)*HLOOKUP(Results!$B$2,Inputs!$B$2:'Inputs'!$L$9,4,FALSE) - PMT(HLOOKUP(Results!$B$2,Inputs!$B$2:'Inputs'!$L$9,6,FALSE),HLOOKUP(Results!$B$2,Inputs!$B$2:'Inputs'!$L$9,5,FALSE),PV(HLOOKUP(Results!$B$2,Inputs!$B$2:'Inputs'!$L$9,6,FALSE),10,Inputs!$B$22)))/(1-Inputs!$B$23) -> 3.3077228 | H7: =((HLOOKUP(Results!$B$2,Inputs!$B$2:$L$11,10,FALSE)/($A7*8760)+H$3/1000)*HLOOKUP(Results!$B$2,Inputs!$B$2:'Inputs'!$L$9,4,FALSE) - PMT(HLOOKUP(Results!$B$2,Inputs!$B$2:'Inputs'!$L$9,6,FALSE),HLOOKUP(Results!$B$2,Inputs!$B$2:'Inputs'!$L$9,5,FALSE),PV(HLOOKUP(Results!$B$2,Inputs!$B$2:'Inputs'!$L$9,6,FALSE),10,Inputs!$B$22)))/(1-Inputs!$B$23) -> 3.8077228
A8: 0.4 | B8: =((HLOOKUP(Results!$B$2,Inputs!$B$2:$L$11,10,FALSE)/($A8*8760)+B$3/1000)*HLOOKUP(Results!$B$2,Inputs!$B$2:'Inputs'!$L$9,4,FALSE) - PMT(HLOOKUP(Results!$B$2,Inputs!$B$2:'Inputs'!$L$9,6,FALSE),HLOOKUP(Results!$B$2,Inputs!$B$2:'Inputs'!$L$9,5,FALSE),PV(HLOOKUP(Results!$B$2,Inputs!$B$2:'Inputs'!$L$9,6,FALSE),10,Inputs!$B$22)))/(1-Inputs!$B$23) -> -0.14420788 | C8: =((HLOOKUP(Results!$B$2,Inputs!$B$2:$L$11,10,FALSE)/($A8*8760)+C$3/1000)*HLOOKUP(Results!$B$2,Inputs!$B$2:'Inputs'!$L$9,4,FALSE) - PMT(HLOOKUP(Results!$B$2,Inputs!$B$2:'Inputs'!$L$9,6,FALSE),HLOOKUP(Results!$B$2,Inputs!$B$2:'Inputs'!$L$9,5,FALSE),PV(HLOOKUP(Results!$B$2,Inputs!$B$2:'Inputs'!$L$9,6,FALSE),10,Inputs!$B$22)))/(1-Inputs!$B$23) -> 0.35579212 | D8: =((HLOOKUP(Results!$B$2,Inputs!$B$2:$L$11,10,FALSE)/($A8*8760)+D$3/1000)*HLOOKUP(Results!$B$2,Inputs!$B$2:'Inputs'!$L$9,4,FALSE) - PMT(HLOOKUP(Results!$B$2,Inputs!$B$2:'Inputs'!$L$9,6,FALSE),HLOOKUP(Results!$B$2,Inputs!$B$2:'Inputs'!$L$9,5,FALSE),PV(HLOOKUP(Results!$B$2,Inputs!$B$2:'Inputs'!$L$9,6,FALSE),10,Inputs!$B$22)))/(1-Inputs!$B$23) -> 0.85579212 | E8: =((HLOOKUP(Results!$B$2,Inputs!$B$2:$L$11,10,FALSE)/($A8*8760)+E$3/1000)*HLOOKUP(Results!$B$2,Inputs!$B$2:'Inputs'!$L$9,4,FALSE) - PMT(HLOOKUP(Results!$B$2,Inputs!$B$2:'Inputs'!$L$9,6,FALSE),HLOOKUP(Results!$B$2,Inputs!$B$2:'Inputs'!$L$9,5,FALSE),PV(HLOOKUP(Results!$B$2,Inputs!$B$2:'Inputs'!$L$9,6,FALSE),10,Inputs!$B$22)))/(1-Inputs!$B$23) -> 1.3557921 | F8: =((HLOOKUP(Results!$B$2,Inputs!$B$2:$L$11,10,FALSE)/($A8*8760)+F$3/1000)*HLOOKUP(Results!$B$2,Inputs!$B$2:'Inputs'!$L$9,4,FALSE) - PMT(HLOOKUP(Results!$B$2,Inputs!$B$2:'Inputs'!$L$9,6,FALSE),HLOOKUP(Results!$B$2,Inputs!$B$2:'Inputs'!$L$9,5,FALSE),PV(HLOOKUP(Results!$B$2,Inputs!$B$2:'Inputs'!$L$9,6,FALSE),10,Inputs!$B$22)))/(1-Inputs!$B$23) -> 1.8557921 | G8: =((HLOOKUP(Results!$B$2,Inputs!$B$2:$L$11,10,FALSE)/($A8*8760)+G$3/1000)*HLOOKUP(Results!$B$2,Inputs!$B$2:'Inputs'!$L$9,4,FALSE) - PMT(HLOOKUP(Results!$B$2,Inputs!$B$2:'Inputs'!$L$9,6,FALSE),HLOOKUP(Results!$B$2,Inputs!$B$2:'Inputs'!$L$9,5,FALSE),PV(HLOOKUP(Results!$B$2,Inputs!$B$2:'Inputs'!$L$9,6,FALSE),10,Inputs!$B$22)))/(1-Inputs!$B$23) -> 2.3557921 | H8: =((HLOOKUP(Results!$B$2,Inputs!$B$2:$L$11,10,FALSE)/($A8*8760)+H$3/1000)*HLOOKUP(Results!$B$2,Inputs!$B$2:'Inputs'!$L$9,4,FALSE) - PMT(HLOOKUP(Results!$B$2,Inputs!$B$2:'Inputs'!$L$9,6,FALSE),HLOOKUP(Results!$B$2,Inputs!$B$2:'Inputs'!$L$9,5,FALSE),PV(HLOOKUP(Results!$B$2,Inputs!$B$2:'Inputs'!$L$9,6,FALSE),10,Inputs!$B$22)))/(1-Inputs!$B$23) -> 2.8557921
A9: 0.5 | B9: =((HLOOKUP(Results!$B$2,Inputs!$B$2:$L$11,10,FALSE)/($A9*8760)+B$3/1000)*HLOOKUP(Results!$B$2,Inputs!$B$2:'Inputs'!$L$9,4,FALSE) - PMT(HLOOKUP(Results!$B$2,Inputs!$B$2:'Inputs'!$L$9,6,FALSE),HLOOKUP(Results!$B$2,Inputs!$B$2:'Inputs'!$L$9,5,FALSE),PV(HLOOKUP(Results!$B$2,Inputs!$B$2:'Inputs'!$L$9,6,FALSE),10,Inputs!$B$22)))/(1-Inputs!$B$23) -> -0.7153663 | C9: =((HLOOKUP(Results!$B$2,Inputs!$B$2:$L$11,10,FALSE)/($A9*8760)+C$3/1000)*HLOOKUP(Results!$B$2,Inputs!$B$2:'Inputs'!$L$9,4,FALSE) - PMT(HLOOKUP(Results!$B$2,Inputs!$B$2:'Inputs'!$L$9,6,FALSE),HLOOKUP(Results!$B$2,Inputs!$B$2:'Inputs'!$L$9,5,FALSE),PV(HLOOKUP(Results!$B$2,Inputs!$B$2:'Inputs'!$L$9,6,FALSE),10,Inputs!$B$22)))/(1-Inputs!$B$23) -> -0.2153663 | D9: =((HLOOKUP(Results!$B$2,Inputs!$B$2:$L$11,10,FALSE)/($A9*8760)+D$3/1000)*HLOOKUP(Results!$B$2,Inputs!$B$2:'Inputs'!$L$9,4,FALSE) - PMT(HLOOKUP(Results!$B$2,Inputs!$B$2:'Inputs'!$L$9,6,FALSE),HLOOKUP(Results!$B$2,Inputs!$B$2:'Inputs'!$L$9,5,FALSE),PV(HLOOKUP(Results!$B$2,Inputs!$B$2:'Inputs'!$L$9,6,FALSE),10,Inputs!$B$22)))/(1-Inputs!$B$23) -> 0.2846337 | E9: =((HLOOKUP(Results!$B$2,Inputs!$B$2:$L$11,10,FALSE)/($A9*8760)+E$3/1000)*HLOOKUP(Results!$B$2,Inputs!$B$2:'Inputs'!$L$9,4,FALSE) - PMT(HLOOKUP(Results!$B$2,Inputs!$B$2:'Inputs'!$L$9,6,FALSE),HLOOKUP(Results!$B$2,Inputs!$B$2:'Inputs'!$L$9,5,FALSE),PV(HLOOKUP(Results!$B$2,Inputs!$B$2:'Inputs'!$L$9,6,FALSE),10,Inputs!$B$22)))/(1-Inputs!$B$23) -> 0.7846337 | F9: =((HLOOKUP(Results!$B$2,Inputs!$B$2:$L$11,10,FALSE)/($A9*8760)+F$3/1000)*HLOOKUP(Results!$B$2,Inputs!$B$2:'Inputs'!$L$9,4,FALSE) - PMT(HLOOKUP(Results!$B$2,Inputs!$B$2:'Inputs'!$L$9,6,FALSE),HLOOKUP(Results!$B$2,Inputs!$B$2:'Inputs'!$L$9,5,FALSE),PV(HLOOKUP(Results!$B$2,Inputs!$B$2:'Inputs'!$L$9,6,FALSE),10,Inputs!$B$22)))/(1-Inputs!$B$23) -> 1.2846337 | G9: =((HLOOKUP(Results!$B$2,Inputs!$B$2:$L$11,10,FALSE)/($A9*8760)+G$3/1000)*HLOOKUP(Results!$B$2,Inputs!$B$2:'Inputs'!$L$9,4,FALSE) - PMT(HLOOKUP(Results!$B$2,Inputs!$B$2:'Inputs'!$L$9,6,FALSE),HLOOKUP(Results!$B$2,Inputs!$B$2:'Inputs'!$L$9,5,FALSE),PV(HLOOKUP(Results!$B$2,Inputs!$B$2:'Inputs'!$L$9,6,FALSE),10,Inputs!$B$22)))/(1-Inputs!$B$23) -> 1.7846337 | H9: =((HLOOKUP(Results!$B$2,Inputs!$B$2:$L$11,10,FALSE)/($A9*8760)+H$3/1000)*HLOOKUP(Results!$B$2,Inputs!$B$2:'Inputs'!$L$9,4,FALSE) - PMT(HLOOKUP(Results!$B$2,Inputs!$B$2:'Inputs'!$L$9,6,FALSE),HLOOKUP(Results!$B$2,Inputs!$B$2:'Inputs'!$L$9,5,FALSE),PV(HLOOKUP(Results!$B$2,Inputs!$B$2:'Inputs'!$L$9,6,FALSE),10,Inputs!$B$22)))/(1-Inputs!$B$23) -> 2.2846337
A10: 0.6 | B10: =((HLOOKUP(Results!$B$2,Inputs!$B$2:$L$11,10,FALSE)/($A10*8760)+B$3/1000)*HLOOKUP(Results!$B$2,Inputs!$B$2:'Inputs'!$L$9,4,FALSE) - PMT(HLOOKUP(Results!$B$2,Inputs!$B$2:'Inputs'!$L$9,6,FALSE),HLOOKUP(Results!$B$2,Inputs!$B$2:'Inputs'!$L$9,5,FALSE),PV(HLOOKUP(Results!$B$2,Inputs!$B$2:'Inputs'!$L$9,6,FALSE),10,Inputs!$B$22)))/(1-Inputs!$B$23) -> -1.0961386 | C10: =((HLOOKUP(Results!$B$2,Inputs!$B$2:$L$11,10,FALSE)/($A10*8760)+C$3/1000)*HLOOKUP(Results!$B$2,Inputs!$B$2:'Inputs'!$L$9,4,FALSE) - PMT(HLOOKUP(Results!$B$2,Inputs!$B$2:'Inputs'!$L$9,6,FALSE),HLOOKUP(Results!$B$2,Inputs!$B$2:'Inputs'!$L$9,5,FALSE),PV(HLOOKUP(Results!$B$2,Inputs!$B$2:'Inputs'!$L$9,6,FALSE),10,Inputs!$B$22)))/(1-Inputs!$B$23) -> -0.59613858 | D10: =((HLOOKUP(Results!$B$2,Inputs!$B$2:$L$11,10,FALSE)/($A10*8760)+D$3/1000)*HLOOKUP(Results!$B$2,Inputs!$B$2:'Inputs'!$L$9,4,FALSE) - PMT(HLOOKUP(Results!$B$2,Inputs!$B$2:'Inputs'!$L$9,6,FALSE),HLOOKUP(Results!$B$2,Inputs!$B$2:'Inputs'!$L$9,5,FALSE),PV(HLOOKUP(Results!$B$2,Inputs!$B$2:'Inputs'!$L$9,6,FALSE),10,Inputs!$B$22)))/(1-Inputs!$B$23) -> -0.096138584 | E10: =((HLOOKUP(Results!$B$2,Inputs!$B$2:$L$11,10,FALSE)/($A10*8760)+E$3/1000)*HLOOKUP(Results!$B$2,Inputs!$B$2:'Inputs'!$L$9,4,FALSE) - PMT(HLOOKUP(Results!$B$2,Inputs!$B$2:'Inputs'!$L$9,6,FALSE),HLOOKUP(Results!$B$2,Inputs!$B$2:'Inputs'!$L$9,5,FALSE),PV(HLOOKUP(Results!$B$2,Inputs!$B$2:'Inputs'!$L$9,6,FALSE),10,Inputs!$B$22)))/(1-Inputs!$B$23) -> 0.40386142 | F10: =((HLOOKUP(Results!$B$2,Inputs!$B$2:$L$11,10,FALSE)/($A10*8760)+F$3/1000)*HLOOKUP(Results!$B$2,Inputs!$B$2:'Inputs'!$L$9,4,FALSE) - PMT(HLOOKUP(Results!$B$2,Inputs!$B$2:'Inputs'!$L$9,6,FALSE),HLOOKUP(Results!$B$2,Inputs!$B$2:'Inputs'!$L$9,5,FALSE),PV(HLOOKUP(Results!$B$2,Inputs!$B$2:'Inputs'!$L$9,6,FALSE),10,Inputs!$B$22)))/(1-Inputs!$B$23) -> 0.90386142 | G10: =((HLOOKUP(Results!$B$2,Inputs!$B$2:$L$11,10,FALSE)/($A10*8760)+G$3/1000)*HLOOKUP(Results!$B$2,Inputs!$B$2:'Inputs'!$L$9,4,FALSE) - PMT(HLOOKUP(Results!$B$2,Inputs!$B$2:'Inputs'!$L$9,6,FALSE),HLOOKUP(Results!$B$2,Inputs!$B$2:'Inputs'!$L$9,5,FALSE),PV(HLOOKUP(Results!$B$2,Inputs!$B$2:'Inputs'!$L$9,6,FALSE),10,Inputs!$B$22)))/(1-Inputs!$B$23) -> 1.4038614 | H10: =((HLOOKUP(Results!$B$2,Inputs!$B$2:$L$11,10,FALSE)/($A10*8760)+H$3/1000)*HLOOKUP(Results!$B$2,Inputs!$B$2:'Inputs'!$L$9,4,FALSE) - PMT(HLOOKUP(Results!$B$2,Inputs!$B$2:'Inputs'!$L$9,6,FALSE),HLOOKUP(Results!$B$2,Inputs!$B$2:'Inputs'!$L$9,5,FALSE),PV(HLOOKUP(Results!$B$2,Inputs!$B$2:'Inputs'!$L$9,6,FALSE),10,Inputs!$B$22)))/(1-Inputs!$B$23) -> 1.9038614
A11: 0.7 | B11: =((HLOOKUP(Results!$B$2,Inputs!$B$2:$L$11,10,FALSE)/($A11*8760)+B$3/1000)*HLOOKUP(Results!$B$2,Inputs!$B$2:'Inputs'!$L$9,4,FALSE) - PMT(HLOOKUP(Results!$B$2,Inputs!$B$2:'Inputs'!$L$9,6,FALSE),HLOOKUP(Results!$B$2,Inputs!$B$2:'Inputs'!$L$9,5,FALSE),PV(HLOOKUP(Results!$B$2,Inputs!$B$2:'Inputs'!$L$9,6,FALSE),10,Inputs!$B$22)))/(1-Inputs!$B$23) -> -1.3681188 | C11: =((HLOOKUP(Results!$B$2,Inputs!$B$2:$L$11,10,FALSE)/($A11*8760)+C$3/1000)*HLOOKUP(Results!$B$2,Inputs!$B$2:'Inputs'!$L$9,4,FALSE) - PMT(HLOOKUP(Results!$B$2,Inputs!$B$2:'Inputs'!$L$9,6,FALSE),HLOOKUP(Results!$B$2,Inputs!$B$2:'Inputs'!$L$9,5,FALSE),PV(HLOOKUP(Results!$B$2,Inputs!$B$2:'Inputs'!$L$9,6,FALSE),10,Inputs!$B$22)))/(1-Inputs!$B$23) -> -0.86811879 | D11: =((HLOOKUP(Results!$B$2,Inputs!$B$2:$L$11,10,FALSE)/($A11*8760)+D$3/1000)*HLOOKUP(Results!$B$2,Inputs!$B$2:'Inputs'!$L$9,4,FALSE) - PMT(HLOOKUP(Results!$B$2,Inputs!$B$2:'Inputs'!$L$9,6,FALSE),HLOOKUP(Results!$B$2,Inputs!$B$2:'Inputs'!$L$9,5,FALSE),PV(HLOOKUP(Results!$B$2,Inputs!$B$2:'Inputs'!$L$9,6,FALSE),10,Inputs!$B$22)))/(1-Inputs!$B$23) -> -0.36811879 | E11: =((HLOOKUP(Results!$B$2,Inputs!$B$2:$L$11,10,FALSE)/($A11*8760)+E$3/1000)*HLOOKUP(Results!$B$2,Inputs!$B$2:'Inputs'!$L$9,4,FALSE) - PMT(HLOOKUP(Results!$B$2,Inputs!$B$2:'Inputs'!$L$9,6,FALSE),HLOOKUP(Results!$B$2,Inputs!$B$2:'Inputs'!$L$9,5,FALSE),PV(HLOOKUP(Results!$B$2,Inputs!$B$2:'Inputs'!$L$9,6,FALSE),10,Inputs!$B$22)))/(1-Inputs!$B$23) -> 0.13188121 | F11: =((HLOOKUP(Results!$B$2,Inputs!$B$2:$L$11,10,FALSE)/($A11*8760)+F$3/1000)*HLOOKUP(Results!$B$2,Inputs!$B$2:'Inputs'!$L$9,4,FALSE) - PMT(HLOOKUP(Results!$B$2,Inputs!$B$2:'Inputs'!$L$9,6,FALSE),HLOOKUP(Results!$B$2,Inputs!$B$2:'Inputs'!$L$9,5,FALSE),PV(HLOOKUP(Results!$B$2,Inputs!$B$2:'Inputs'!$L$9,6,FALSE),10,Inputs!$B$22)))/(1-Inputs!$B$23) -> 0.63188121 | G11: =((HLOOKUP(Results!$B$2,Inputs!$B$2:$L$11,10,FALSE)/($A11*8760)+G$3/1000)*HLOOKUP(Results!$B$2,Inputs!$B$2:'Inputs'!$L$9,4,FALSE) - PMT(HLOOKUP(Results!$B$2,Inputs!$B$2:'Inputs'!$L$9,6,FALSE),HLOOKUP(Results!$B$2,Inputs!$B$2:'Inputs'!$L$9,5,FALSE),PV(HLOOKUP(Results!$B$2,Inputs!$B$2:'Inputs'!$L$9,6,FALSE),10,Inputs!$B$22)))/(1-Inputs!$B$23) -> 1.1318812 | H11: =((HLOOKUP(Results!$B$2,Inputs!$B$2:$L$11,10,FALSE)/($A11*8760)+H$3/1000)*HLOOKUP(Results!$B$2,Inputs!$B$2:'Inputs'!$L$9,4,FALSE) - PMT(HLOOKUP(Results!$B$2,Inputs!$B$2:'Inputs'!$L$9,6,FALSE),HLOOKUP(Results!$B$2,Inputs!$B$2:'Inputs'!$L$9,5,FALSE),PV(HLOOKUP(Results!$B$2,Inputs!$B$2:'Inputs'!$L$9,6,FALSE),10,Inputs!$B$22)))/(1-Inputs!$B$23) -> 1.6318812
A12: 0.8 | B12: =((HLOOKUP(Results!$B$2,Inputs!$B$2:$L$11,10,FALSE)/($A12*8760)+B$3/1000)*HLOOKUP(Results!$B$2,Inputs!$B$2:'Inputs'!$L$9,4,FALSE) - PMT(HLOOKUP(Results!$B$2,Inputs!$B$2:'Inputs'!$L$9,6,FALSE),HLOOKUP(Results!$B$2,Inputs!$B$2:'Inputs'!$L$9,5,FALSE),PV(HLOOKUP(Results!$B$2,Inputs!$B$2:'Inputs'!$L$9,6,FALSE),10,Inputs!$B$22)))/(1-Inputs!$B$23) -> -1.5721039 | C12: =((HLOOKUP(Results!$B$2,Inputs!$B$2:$L$11,10,FALSE)/($A12*8760)+C$3/1000)*HLOOKUP(Results!$B$2,Inputs!$B$2:'Inputs'!$L$9,4,FALSE) - PMT(HLOOKUP(Results!$B$2,Inputs!$B$2:'Inputs'!$L$9,6,FALSE),HLOOKUP(Results!$B$2,Inputs!$B$2:'Inputs'!$L$9,5,FALSE),PV(HLOOKUP(Results!$B$2,Inputs!$B$2:'Inputs'!$L$9,6,FALSE),10,Inputs!$B$22)))/(1-Inputs!$B$23) -> -1.0721039 | D12: =((HLOOKUP(Results!$B$2,Inputs!$B$2:$L$11,10,FALSE)/($A12*8760)+D$3/1000)*HLOOKUP(Results!$B$2,Inputs!$B$2:'Inputs'!$L$9,4,FALSE) - PMT(HLOOKUP(Results!$B$2,Inputs!$B$2:'Inputs'!$L$9,6,FALSE),HLOOKUP(Results!$B$2,Inputs!$B$2:'Inputs'!$L$9,5,FALSE),PV(HLOOKUP(Results!$B$2,Inputs!$B$2:'Inputs'!$L$9,6,FALSE),10,Inputs!$B$22)))/(1-Inputs!$B$23) -> -0.57210394 | E12: =((HLOOKUP(Results!$B$2,Inputs!$B$2:$L$11,10,FALSE)/($A12*8760)+E$3/1000)*HLOOKUP(Results!$B$2,Inputs!$B$2:'Inputs'!$L$9,4,FALSE) - PMT(HLOOKUP(Results!$B$2,Inputs!$B$2:'Inputs'!$L$9,6,FALSE),HLOOKUP(Results!$B$2,Inputs!$B$2:'Inputs'!$L$9,5,FALSE),PV(HLOOKUP(Results!$B$2,Inputs!$B$2:'Inputs'!$L$9,6,FALSE),10,Inputs!$B$22)))/(1-Inputs!$B$23) -> -0.072103938 | F12: =((HLOOKUP(Results!$B$2,Inputs!$B$2:$L$11,10,FALSE)/($A12*8760)+F$3/1000)*HLOOKUP(Results!$B$2,Inputs!$B$2:'Inputs'!$L$9,4,FALSE) - PMT(HLOOKUP(Results!$B$2,Inputs!$B$2:'Inputs'!$L$9,6,FALSE),HLOOKUP(Results!$B$2,Inputs!$B$2:'Inputs'!$L$9,5,FALSE),PV(HLOOKUP(Results!$B$2,Inputs!$B$2:'Inputs'!$L$9,6,FALSE),10,Inputs!$B$22)))/(1-Inputs!$B$23) -> 0.42789606 | G12: =((HLOOKUP(Results!$B$2,Inputs!$B$2:$L$11,10,FALSE)/($A12*8760)+G$3/1000)*HLOOKUP(Results!$B$2,Inputs!$B$2:'Inputs'!$L$9,4,FALSE) - PMT(HLOOKUP(Results!$B$2,Inputs!$B$2:'Inputs'!$L$9,6,FALSE),HLOOKUP(Results!$B$2,Inputs!$B$2:'Inputs'!$L$9,5,FALSE),PV(HLOOKUP(Results!$B$2,Inputs!$B$2:'Inputs'!$L$9,6,FALSE),10,Inputs!$B$22)))/(1-Inputs!$B$23) -> 0.92789606 | H12: =((HLOOKUP(Results!$B$2,Inputs!$B$2:$L$11,10,FALSE)/($A12*8760)+H$3/1000)*HLOOKUP(Results!$B$2,Inputs!$B$2:'Inputs'!$L$9,4,FALSE) - PMT(HLOOKUP(Results!$B$2,Inputs!$B$2:'Inputs'!$L$9,6,FALSE),HLOOKUP(Results!$B$2,Inputs!$B$2:'Inputs'!$L$9,5,FALSE),PV(HLOOKUP(Results!$B$2,Inputs!$B$2:'Inputs'!$L$9,6,FALSE),10,Inputs!$B$22)))/(1-Inputs!$B$23) -> 1.4278961
A13: 0.9 | B13: =((HLOOKUP(Results!$B$2,Inputs!$B$2:$L$11,10,FALSE)/($A13*8760)+B$3/1000)*HLOOKUP(Results!$B$2,Inputs!$B$2:'Inputs'!$L$9,4,FALSE) - PMT(HLOOKUP(Results!$B$2,Inputs!$B$2:'Inputs'!$L$9,6,FALSE),HLOOKUP(Results!$B$2,Inputs!$B$2:'Inputs'!$L$9,5,FALSE),PV(HLOOKUP(Results!$B$2,Inputs!$B$2:'Inputs'!$L$9,6,FALSE),10,Inputs!$B$22)))/(1-Inputs!$B$23) -> -1.7307591 | C13: =((HLOOKUP(Results!$B$2,Inputs!$B$2:$L$11,10,FALSE)/($A13*8760)+C$3/1000)*HLOOKUP(Results!$B$2,Inputs!$B$2:'Inputs'!$L$9,4,FALSE) - PMT(HLOOKUP(Results!$B$2,Inputs!$B$2:'Inputs'!$L$9,6,FALSE),HLOOKUP(Results!$B$2,Inputs!$B$2:'Inputs'!$L$9,5,FALSE),PV(HLOOKUP(Results!$B$2,Inputs!$B$2:'Inputs'!$L$9,6,FALSE),10,Inputs!$B$22)))/(1-Inputs!$B$23) -> -1.2307591 | D13: =((HLOOKUP(Results!$B$2,Inputs!$B$2:$L$11,10,FALSE)/($A13*8760)+D$3/1000)*HLOOKUP(Results!$B$2,Inputs!$B$2:'Inputs'!$L$9,4,FALSE) - PMT(HLOOKUP(Results!$B$2,Inputs!$B$2:'Inputs'!$L$9,6,FALSE),HLOOKUP(Results!$B$2,Inputs!$B$2:'Inputs'!$L$9,5,FALSE),PV(HLOOKUP(Results!$B$2,Inputs!$B$2:'Inputs'!$L$9,6,FALSE),10,Inputs!$B$22)))/(1-Inputs!$B$23) -> -0.73075906 | E13: =((HLOOKUP(Results!$B$2,Inputs!$B$2:$L$11,10,FALSE)/($A13*8760)+E$3/1000)*HLOOKUP(Results!$B$2,Inputs!$B$2:'Inputs'!$L$9,4,FALSE) - PMT(HLOOKUP(Results!$B$2,Inputs!$B$2:'Inputs'!$L$9,6,FALSE),HLOOKUP(Results!$B$2,Inputs!$B$2:'Inputs'!$L$9,5,FALSE),PV(HLOOKUP(Results!$B$2,Inputs!$B$2:'Inputs'!$L$9,6,FALSE),10,Inputs!$B$22)))/(1-Inputs!$B$23) -> -0.23075906 | F13: =((HLOOKUP(Results!$B$2,Inputs!$B$2:$L$11,10,FALSE)/($A13*8760)+F$3/1000)*HLOOKUP(Results!$B$2,Inputs!$B$2:'Inputs'!$L$9,4,FALSE) - PMT(HLOOKUP(Results!$B$2,Inputs!$B$2:'Inputs'!$L$9,6,FALSE),HLOOKUP(Results!$B$2,Inputs!$B$2:'Inputs'!$L$9,5,FALSE),PV(HLOOKUP(Results!$B$2,Inputs!$B$2:'Inputs'!$L$9,6,FALSE),10,Inputs!$B$22)))/(1-Inputs!$B$23) -> 0.26924094 | G13: =((HLOOKUP(Results!$B$2,Inputs!$B$2:$L$11,10,FALSE)/($A13*8760)+G$3/1000)*HLOOKUP(Results!$B$2,Inputs!$B$2:'Inputs'!$L$9,4,FALSE) - PMT(HLOOKUP(Results!$B$2,Inputs!$B$2:'Inputs'!$L$9,6,FALSE),HLOOKUP(Results!$B$2,Inputs!$B$2:'Inputs'!$L$9,5,FALSE),PV(HLOOKUP(Results!$B$2,Inputs!$B$2:'Inputs'!$L$9,6,FALSE),10,Inputs!$B$22)))/(1-Inputs!$B$23) -> 0.76924094 | H13: =((HLOOKUP(Results!$B$2,Inputs!$B$2:$L$11,10,FALSE)/($A13*8760)+H$3/1000)*HLOOKUP(Results!$B$2,Inputs!$B$2:'Inputs'!$L$9,4,FALSE) - PMT(HLOOKUP(Results!$B$2,Inputs!$B$2:'Inputs'!$L$9,6,FALSE),HLOOKUP(Results!$B$2,Inputs!$B$2:'Inputs'!$L$9,5,FALSE),PV(HLOOKUP(Results!$B$2,Inputs!$B$2:'Inputs'!$L$9,6,FALSE),10,Inputs!$B$22)))/(1-Inputs!$B$23) -> 1.2692409
A14: 1 | B14: =((HLOOKUP(Results!$B$2,Inputs!$B$2:$L$11,10,FALSE)/($A14*8760)+B$3/1000)*HLOOKUP(Results!$B$2,Inputs!$B$2:'Inputs'!$L$9,4,FALSE) - PMT(HLOOKUP(Results!$B$2,Inputs!$B$2:'Inputs'!$L$9,6,FALSE),HLOOKUP(Results!$B$2,Inputs!$B$2:'Inputs'!$L$9,5,FALSE),PV(HLOOKUP(Results!$B$2,Inputs!$B$2:'Inputs'!$L$9,6,FALSE),10,Inputs!$B$22)))/(1-Inputs!$B$23) -> -1.8576832 | C14: =((HLOOKUP(Results!$B$2,Inputs!$B$2:$L$11,10,FALSE)/($A14*8760)+C$3/1000)*HLOOKUP(Results!$B$2,Inputs!$B$2:'Inputs'!$L$9,4,FALSE) - PMT(HLOOKUP(Results!$B$2,Inputs!$B$2:'Inputs'!$L$9,6,FALSE),HLOOKUP(Results!$B$2,Inputs!$B$2:'Inputs'!$L$9,5,FALSE),PV(HLOOKUP(Results!$B$2,Inputs!$B$2:'Inputs'!$L$9,6,FALSE),10,Inputs!$B$22)))/(1-Inputs!$B$23) -> -1.3576832 | D14: =((HLOOKUP(Results!$B$2,Inputs!$B$2:$L$11,10,FALSE)/($A14*8760)+D$3/1000)*HLOOKUP(Results!$B$2,Inputs!$B$2:'Inputs'!$L$9,4,FALSE) - PMT(HLOOKUP(Results!$B$2,Inputs!$B$2:'Inputs'!$L$9,6,FALSE),HLOOKUP(Results!$B$2,Inputs!$B$2:'Inputs'!$L$9,5,FALSE),PV(HLOOKUP(Results!$B$2,Inputs!$B$2:'Inputs'!$L$9,6,FALSE),10,Inputs!$B$22)))/(1-Inputs!$B$23) -> -0.85768315 | E14: =((HLOOKUP(Results!$B$2,Inputs!$B$2:$L$11,10,FALSE)/($A14*8760)+E$3/1000)*HLOOKUP(Results!$B$2,Inputs!$B$2:'Inputs'!$L$9,4,FALSE) - PMT(HLOOKUP(Results!$B$2,Inputs!$B$2:'Inputs'!$L$9,6,FALSE),HLOOKUP(Results!$B$2,Inputs!$B$2:'Inputs'!$L$9,5,FALSE),PV(HLOOKUP(Results!$B$2,Inputs!$B$2:'Inputs'!$L$9,6,FALSE),10,Inputs!$B$22)))/(1-Inputs!$B$23) -> -0.35768315 | F14: =((HLOOKUP(Results!$B$2,Inputs!$B$2:$L$11,10,FALSE)/($A14*8760)+F$3/1000)*HLOOKUP(Results!$B$2,Inputs!$B$2:'Inputs'!$L$9,4,FALSE) - PMT(HLOOKUP(Results!$B$2,Inputs!$B$2:'Inputs'!$L$9,6,FALSE),HLOOKUP(Results!$B$2,Inputs!$B$2:'Inputs'!$L$9,5,FALSE),PV(HLOOKUP(Results!$B$2,Inputs!$B$2:'Inputs'!$L$9,6,FALSE),10,Inputs!$B$22)))/(1-Inputs!$B$23) -> 0.14231685 | G14: =((HLOOKUP(Results!$B$2,Inputs!$B$2:$L$11,10,FALSE)/($A14*8760)+G$3/1000)*HLOOKUP(Results!$B$2,Inputs!$B$2:'Inputs'!$L$9,4,FALSE) - PMT(HLOOKUP(Results!$B$2,Inputs!$B$2:'Inputs'!$L$9,6,FALSE),HLOOKUP(Results!$B$2,Inputs!$B$2:'Inputs'!$L$9,5,FALSE),PV(HLOOKUP(Results!$B$2,Inputs!$B$2:'Inputs'!$L$9,6,FALSE),10,Inputs!$B$22)))/(1-Inputs!$B$23) -> 0.64231685 | H14: =((HLOOKUP(Results!$B$2,Inputs!$B$2:$L$11,10,FALSE)/($A14*8760)+H$3/1000)*HLOOKUP(Results!$B$2,Inputs!$B$2:'Inputs'!$L$9,4,FALSE) - PMT(HLOOKUP(Results!$B$2,Inputs!$B$2:'Inputs'!$L$9,6,FALSE),HLOOKUP(Results!$B$2,Inputs!$B$2:'Inputs'!$L$9,5,FALSE),PV(HLOOKUP(Results!$B$2,Inputs!$B$2:'Inputs'!$L$9,6,FALSE),10,Inputs!$B$22)))/(1-Inputs!$B$23) -> 1.1423168
A16: Note: The below chart illustrates LCOH as a function of electrolyzer utilization rate and average electricity cost for the fixed facility cost chosen above. Markers indicating utilization and electricity cost results from each of the listed studies are also shown. Filled markers indicate studies that allowed both oversizing of clean generating capacity and sales of excess clean generation. Patterned markers indicate studies that allowed oversizing but not excess sales. Unfilled markers indicate studies that assumed clean generating capacity to be equal to electrolyzer capacity.

Sheet Notes
A1: 1. Increased financial lifetime lowers the fixed cost portion of LCOH but also reduces the lifetime average value of the tax credit, which is only received for the first 10 years of operations. For some combinations of fixed costs and tax credit sizes, increasing financial lifetime can actually increase the final LCOH.
A2: 2. This comparison tool uses a simplified LCOH calculation that incorporates only the financial parameters listed in rows 4 through 9 in the Inputs tab, and an effective tax rate set in cell B23. The default tax rate is set to 0% on the assumption that until project breakeven is achieved, developers will not have tax exposure. Real project levelized costs will also depend on context-specific tax rates, depreciation schedules, government incentives such as loan guarantees and hydrogen hub grants, and other factors.
A3: 3. The Energy Innovation LLC and Wood Mackenzie studies both include a fixed cost component for "financing and tax shield." This is ignored in this tool to allow for consistent treatment of taxes across studies using the effective tax rate value in cell B23.
A4: 4. The E3/ACORE study does not report final electricity costs and utilization rates. It is also the only study to model electrolyzer O&M costs as variable costs ($10/MWh), rather than fixed costs. We include only the report's fixed cost data, with a fixed O&M rate chosen to approximate the impact of the $10/MWh variable O&M cost at a 90% utilization rate.

Sheet Calculations
A1: Inputs List | F1: Electrolyzer Utilization Rate | G1: 60 | H1: 50 | I1: 40 | J1: 30 | K1: 20 | L1: 10 | M1: 0 | N1: Electrolyzer Utilization Rate | O1: Princeton ZERO Lab, Wind and Solar [PNW] | P1: Electrolyzer Utilization Rate | Q1: Princeton ZERO Lab, Solar and Batteries [N. CA] | R1: Electrolyzer Utilization Rate | S1: Electric Hydrogen, Wind and Solar [Avg.] | T1: Electrolyzer Utilization Rate | U1: Energy Innovation LLC, Wind and Solar [Avg.] | V1: Electrolyzer Utilization Rate | W1: Rhodium Group, Solar Only | X1: Electrolyzer Utilization Rate | Y1: Wood Mackenzie, Wind and Solar [TX] | Z1: Electrolyzer Utilization Rate | AA1: Wood Mackenzie, Solar Only [AZ] | AB1: Electrolyzer Utilization Rate | AC1: Energy Futures Initiative, Wind Only [TX] | AD1: Electrolyzer Utilization Rate | AE1: User Inputs | AF1: Electrolyzer Utilization Rate | AG1: Target Price | AH1: Electrolyzer Utilization Rate | AI1: Clean Energy Developer 1, Wind and Solar [TX] | AJ1: Electrolyzer Utilization Rate | AK1: Clean Energy Developer 2, Wind and Solar | AL1: Electrolyzer Utilization Rate | AM1: Clean Energy Developer 2, Wind Only | AN1: Electrolyzer Utilization Rate | AO1: Clean Energy Developer 2, Solar Only | AP1: Electrolyzer Utilization Rate | AQ1: MIT Energy Initiative, Wind and Solar [FL] | AR1: Electrolyzer Utilization Rate | AS1: MIT Energy Initiative, Wind and Solar [TX]
A2: User Inputs | F2: 0.02 | G2: =((HLOOKUP(Results!$B$2,Inputs!$B$2:$L$11,10,FALSE)/($F2*8760)+G$1/1000)*HLOOKUP(Results!$B$2,Inputs!$B$2:'Inputs'!$L$9,4,FALSE) - PMT(HLOOKUP(Results!$B$2,Inputs!$B$2:'Inputs'!$L$9,6,FALSE),HLOOKUP(Results!$B$2,Inputs!$B$2:'Inputs'!$L$9,5,FALSE),PV(HLOOKUP(Results!$B$2,Inputs!$B$2:'Inputs'!$L$9,6,FALSE),10,Inputs!$B$22)))/(1-Inputs!$B$23) -> 57.115842 | H2: =((HLOOKUP(Results!$B$2,Inputs!$B$2:$L$11,10,FALSE)/($F2*8760)+H$1/1000)*HLOOKUP(Results!$B$2,Inputs!$B$2:'Inputs'!$L$9,4,FALSE) - PMT(HLOOKUP(Results!$B$2,Inputs!$B$2:'Inputs'!$L$9,6,FALSE),HLOOKUP(Results!$B$2,Inputs!$B$2:'Inputs'!$L$9,5,FALSE),PV(HLOOKUP(Results!$B$2,Inputs!$B$2:'Inputs'!$L$9,6,FALSE),10,Inputs!$B$22)))/(1-Inputs!$B$23) -> 56.615842 | I2: =((HLOOKUP(Results!$B$2,Inputs!$B$2:$L$11,10,FALSE)/($F2*8760)+I$1/1000)*HLOOKUP(Results!$B$2,Inputs!$B$2:'Inputs'!$L$9,4,FALSE) - PMT(HLOOKUP(Results!$B$2,Inputs!$B$2:'Inputs'!$L$9,6,FALSE),HLOOKUP(Results!$B$2,Inputs!$B$2:'Inputs'!$L$9,5,FALSE),PV(HLOOKUP(Results!$B$2,Inputs!$B$2:'Inputs'!$L$9,6,FALSE),10,Inputs!$B$22)))/(1-Inputs!$B$23) -> 56.115842 | J2: =((HLOOKUP(Results!$B$2,Inputs!$B$2:$L$11,10,FALSE)/($F2*8760)+J$1/1000)*HLOOKUP(Results!$B$2,Inputs!$B$2:'Inputs'!$L$9,4,FALSE) - PMT(HLOOKUP(Results!$B$2,Inputs!$B$2:'Inputs'!$L$9,6,FALSE),HLOOKUP(Results!$B$2,Inputs!$B$2:'Inputs'!$L$9,5,FALSE),PV(HLOOKUP(Results!$B$2,Inputs!$B$2:'Inputs'!$L$9,6,FALSE),10,Inputs!$B$22)))/(1-Inputs!$B$23) -> 55.615842 | K2: =((HLOOKUP(Results!$B$2,Inputs!$B$2:$L$11,10,FALSE)/($F2*8760)+K$1/1000)*HLOOKUP(Results!$B$2,Inputs!$B$2:'Inputs'!$L$9,4,FALSE) - PMT(HLOOKUP(Results!$B$2,Inputs!$B$2:'Inputs'!$L$9,6,FALSE),HLOOKUP(Results!$B$2,Inputs!$B$2:'Inputs'!$L$9,5,FALSE),PV(HLOOKUP(Results!$B$2,Inputs!$B$2:'Inputs'!$L$9,6,FALSE),10,Inputs!$B$22)))/(1-Inputs!$B$23) -> 55.115842 | L2: =((HLOOKUP(Results!$B$2,Inputs!$B$2:$L$11,10,FALSE)/($F2*8760)+L$1/1000)*HLOOKUP(Results!$B$2,Inputs!$B$2:'Inputs'!$L$9,4,FALSE) - PMT(HLOOKUP(Results!$B$2,Inputs!$B$2:'Inputs'!$L$9,6,FALSE),HLOOKUP(Results!$B$2,Inputs!$B$2:'Inputs'!$L$9,5,FALSE),PV(HLOOKUP(Results!$B$2,Inputs!$B$2:'Inputs'!$L$9,6,FALSE),10,Inputs!$B$22)))/(1-Inputs!$B$23) -> 54.615842 | M2: =((HLOOKUP(Results!$B$2,Inputs!$B$2:$L$11,10,FALSE)/($F2*8760)+M$1/1000)*HLOOKUP(Results!$B$2,Inputs!$B$2:'Inputs'!$L$9,4,FALSE) - PMT(HLOOKUP(Results!$B$2,Inputs!$B$2:'Inputs'!$L$9,6,FALSE),HLOOKUP(Results!$B$2,Inputs!$B$2:'Inputs'!$L$9,5,FALSE),PV(HLOOKUP(Results!$B$2,Inputs!$B$2:'Inputs'!$L$9,6,FALSE),10,Inputs!$B$22)))/(1-Inputs!$B$23) -> 54.115842 | N2: 0.92 | O2: =((HLOOKUP(Results!$B$2,Inputs!$B$2:$L$11,10,FALSE)/(N2*8760)+31.96/1000)*HLOOKUP(Results!$B$2,Inputs!$B$2:'Inputs'!$L$9,4,FALSE) - PMT(HLOOKUP(Results!$B$2,Inputs!$B$2:'Inputs'!$L$9,6,FALSE),HLOOKUP(Results!$B$2,Inputs!$B$2:'Inputs'!$L$9,5,FALSE),PV(HLOOKUP(Results!$B$2,Inputs!$B$2:'Inputs'!$L$9,6,FALSE),10,Inputs!$B$22)))/(1-Inputs!$B$23) -> -0.16035125 | P2: 0.71 | Q2: =((HLOOKUP(Results!$B$2,Inputs!$B$2:$L$11,10,FALSE)/(P2*8760)+41.57/1000)*HLOOKUP(Results!$B$2,Inputs!$B$2:'Inputs'!$L$9,4,FALSE) - PMT(HLOOKUP(Results!$B$2,Inputs!$B$2:'Inputs'!$L$9,6,FALSE),HLOOKUP(Results!$B$2,Inputs!$B$2:'Inputs'!$L$9,5,FALSE),PV(HLOOKUP(Results!$B$2,Inputs!$B$2:'Inputs'!$L$9,6,FALSE),10,Inputs!$B$22)))/(1-Inputs!$B$23) -> 0.68739697 | R2: =Inputs!D14/100 -> 0.7 | S2: =((HLOOKUP(Results!$B$2,Inputs!$B$2:$L$11,10,FALSE)/(R2*8760)+25/1000)*HLOOKUP(Results!$B$2,Inputs!$B$2:'Inputs'!$L$9,4,FALSE) - PMT(HLOOKUP(Results!$B$2,Inputs!$B$2:'Inputs'!$L$9,6,FALSE),HLOOKUP(Results!$B$2,Inputs!$B$2:'Inputs'!$L$9,5,FALSE),PV(HLOOKUP(Results!$B$2,Inputs!$B$2:'Inputs'!$L$9,6,FALSE),10,Inputs!$B$22)))/(1-Inputs!$B$23) -> -0.11811879 | T2: 0.85 | U2: =((HLOOKUP(Results!$B$2,Inputs!$B$2:$L$11,10,FALSE)/(T2*8760)+21.5/1000)*HLOOKUP(Results!$B$2,Inputs!$B$2:'Inputs'!$L$9,4,FALSE) - PMT(HLOOKUP(Results!$B$2,Inputs!$B$2:'Inputs'!$L$9,6,FALSE),HLOOKUP(Results!$B$2,Inputs!$B$2:'Inputs'!$L$9,5,FALSE),PV(HLOOKUP(Results!$B$2,Inputs!$B$2:'Inputs'!$L$9,6,FALSE),10,Inputs!$B$22)))/(1-Inputs!$B$23) -> -0.58109782 | V2: 0.26 | W2: =((HLOOKUP(Results!$B$2,Inputs!$B$2:$L$11,10,FALSE)/(V2*8760)+23/1000)*HLOOKUP(Results!$B$2,Inputs!$B$2:'Inputs'!$L$9,4,FALSE) - PMT(HLOOKUP(Results!$B$2,Inputs!$B$2:'Inputs'!$L$9,6,FALSE),HLOOKUP(Results!$B$2,Inputs!$B$2:'Inputs'!$L$9,5,FALSE),PV(HLOOKUP(Results!$B$2,Inputs!$B$2:'Inputs'!$L$9,6,FALSE),10,Inputs!$B$22)))/(1-Inputs!$B$23) -> 2.5435263 | X2: 0.72 | Y2: =((HLOOKUP(Results!$B$2,Inputs!$B$2:$L$11,10,FALSE)/(X2*8760)+32/1000)*HLOOKUP(Results!$B$2,Inputs!$B$2:'Inputs'!$L$9,4,FALSE) - PMT(HLOOKUP(Results!$B$2,Inputs!$B$2:'Inputs'!$L$9,6,FALSE),HLOOKUP(Results!$B$2,Inputs!$B$2:'Inputs'!$L$9,5,FALSE),PV(HLOOKUP(Results!$B$2,Inputs!$B$2:'Inputs'!$L$9,6,FALSE),10,Inputs!$B$22)))/(1-Inputs!$B$23) -> 0.18655118 | Z2: 0.46 | AA2: =((HLOOKUP(Results!$B$2,Inputs!$B$2:$L$11,10,FALSE)/(Z2*8760)+34/1000)*HLOOKUP(Results!$B$2,Inputs!$B$2:'Inputs'!$L$9,4,FALSE) - PMT(HLOOKUP(Results!$B$2,Inputs!$B$2:'Inputs'!$L$9,6,FALSE),HLOOKUP(Results!$B$2,Inputs!$B$2:'Inputs'!$L$9,5,FALSE),PV(HLOOKUP(Results!$B$2,Inputs!$B$2:'Inputs'!$L$9,6,FALSE),10,Inputs!$B$22)))/(1-Inputs!$B$23) -> 1.1832975 | AB2: 0.4 | AC2: =((HLOOKUP(Results!$B$2,Inputs!$B$2:$L$11,10,FALSE)/(AB2*8760)+26/1000)*HLOOKUP(Results!$B$2,Inputs!$B$2:'Inputs'!$L$9,4,FALSE) - PMT(HLOOKUP(Results!$B$2,Inputs!$B$2:'Inputs'!$L$9,6,FALSE),HLOOKUP(Results!$B$2,Inputs!$B$2:'Inputs'!$L$9,5,FALSE),PV(HLOOKUP(Results!$B$2,Inputs!$B$2:'Inputs'!$L$9,6,FALSE),10,Inputs!$B$22)))/(1-Inputs!$B$23) -> 1.1557921 | AD2: =Inputs!B14 -> 0.7 | AE2: =((HLOOKUP(Results!$B$2,Inputs!$B$2:$L$11,10,FALSE)/(AD2*8760)+Inputs!B13/1000)*HLOOKUP(Results!$B$2,Inputs!$B$2:'Inputs'!$L$9,4,FALSE) - PMT(HLOOKUP(Results!$B$2,Inputs!$B$2:'Inputs'!$L$9,6,FALSE),HLOOKUP(Results!$B$2,Inputs!$B$2:'Inputs'!$L$9,5,FALSE),PV(HLOOKUP(Results!$B$2,Inputs!$B$2:'Inputs'!$L$9,6,FALSE),10,Inputs!$B$22)))/(1-Inputs!$B$23) -> 0.13188121 | AF2: 0 | AG2: =Inputs!$B$24 -> 1.25 | AH2: 0.75 | AI2: =((HLOOKUP(Results!$B$2,Inputs!$B$2:$L$11,10,FALSE)/(AH2*8760)+21/1000)*HLOOKUP(Results!$B$2,Inputs!$B$2:'Inputs'!$L$9,4,FALSE) - PMT(HLOOKUP(Results!$B$2,Inputs!$B$2:'Inputs'!$L$9,6,FALSE),HLOOKUP(Results!$B$2,Inputs!$B$2:'Inputs'!$L$9,5,FALSE),PV(HLOOKUP(Results!$B$2,Inputs!$B$2:'Inputs'!$L$9,6,FALSE),10,Inputs!$B$22)))/(1-Inputs!$B$23) -> -0.42691087 | AJ2: 0.7 | AK2: =((HLOOKUP(Results!$B$2,Inputs!$B$2:$L$11,10,FALSE)/(AJ2*8760)+45/1000)*HLOOKUP(Results!$B$2,Inputs!$B$2:'Inputs'!$L$9,4,FALSE) - PMT(HLOOKUP(Results!$B$2,Inputs!$B$2:'Inputs'!$L$9,6,FALSE),HLOOKUP(Results!$B$2,Inputs!$B$2:'Inputs'!$L$9,5,FALSE),PV(HLOOKUP(Results!$B$2,Inputs!$B$2:'Inputs'!$L$9,6,FALSE),10,Inputs!$B$22)))/(1-Inputs!$B$23) -> 0.88188121 | AL2: 0.56 | AM2: =((HLOOKUP(Results!$B$2,Inputs!$B$2:$L$11,10,FALSE)/(AL2*8760)+50/1000)*HLOOKUP(Results!$B$2,Inputs!$B$2:'Inputs'!$L$9,4,FALSE) - PMT(HLOOKUP(Results!$B$2,Inputs!$B$2:'Inputs'!$L$9,6,FALSE),HLOOKUP(Results!$B$2,Inputs!$B$2:'Inputs'!$L$9,5,FALSE),PV(HLOOKUP(Results!$B$2,Inputs!$B$2:'Inputs'!$L$9,6,FALSE),10,Inputs!$B$22)))/(1-Inputs!$B$23) -> 1.5398515 | AN2: 0.35 | AO2: =((HLOOKUP(Results!$B$2,Inputs!$B$2:$L$11,10,FALSE)/(AN2*8760)+30/1000)*HLOOKUP(Results!$B$2,Inputs!$B$2:'Inputs'!$L$9,4,FALSE) - PMT(HLOOKUP(Results!$B$2,Inputs!$B$2:'Inputs'!$L$9,6,FALSE),HLOOKUP(Results!$B$2,Inputs!$B$2:'Inputs'!$L$9,5,FALSE),PV(HLOOKUP(Results!$B$2,Inputs!$B$2:'Inputs'!$L$9,6,FALSE),10,Inputs!$B$22)))/(1-Inputs!$B$23) -> 1.7637624 | AP2: 0.81 | AQ2: =((HLOOKUP(Results!$B$2,Inputs!$B$2:$L$11,10,FALSE)/(AP2*8760)+41/1000)*HLOOKUP(Results!$B$2,Inputs!$B$2:'Inputs'!$L$9,4,FALSE) - PMT(HLOOKUP(Results!$B$2,Inputs!$B$2:'Inputs'!$L$9,6,FALSE),HLOOKUP(Results!$B$2,Inputs!$B$2:'Inputs'!$L$9,5,FALSE),PV(HLOOKUP(Results!$B$2,Inputs!$B$2:'Inputs'!$L$9,6,FALSE),10,Inputs!$B$22)))/(1-Inputs!$B$23) -> 0.46026772 | AR2: 0.83 | AS2: =((HLOOKUP(Results!$B$2,Inputs!$B$2:$L$11,10,FALSE)/(AR2*8760)+27/1000)*HLOOKUP(Results!$B$2,Inputs!$B$2:'Inputs'!$L$9,4,FALSE) - PMT(HLOOKUP(Results!$B$2,Inputs!$B$2:'Inputs'!$L$9,6,FALSE),HLOOKUP(Results!$B$2,Inputs!$B$2:'Inputs'!$L$9,5,FALSE),PV(HLOOKUP(Results!$B$2,Inputs!$B$2:'Inputs'!$L$9,6,FALSE),10,Inputs!$B$22)))/(1-Inputs!$B$23) -> -0.27371464
A3: Princeton ZERO Lab | F3: 0.04 | G3: =((HLOOKUP(Results!$B$2,Inputs!$B$2:$L$11,10,FALSE)/($F3*8760)+G$1/1000)*HLOOKUP(Results!$B$2,Inputs!$B$2:'Inputs'!$L$9,4,FALSE) - PMT(HLOOKUP(Results!$B$2,Inputs!$B$2:'Inputs'!$L$9,6,FALSE),HLOOKUP(Results!$B$2,Inputs!$B$2:'Inputs'!$L$9,5,FALSE),PV(HLOOKUP(Results!$B$2,Inputs!$B$2:'Inputs'!$L$9,6,FALSE),10,Inputs!$B$22)))/(1-Inputs!$B$23) -> 28.557921 | H3: =((HLOOKUP(Results!$B$2,Inputs!$B$2:$L$11,10,FALSE)/($F3*8760)+H$1/1000)*HLOOKUP(Results!$B$2,Inputs!$B$2:'Inputs'!$L$9,4,FALSE) - PMT(HLOOKUP(Results!$B$2,Inputs!$B$2:'Inputs'!$L$9,6,FALSE),HLOOKUP(Results!$B$2,Inputs!$B$2:'Inputs'!$L$9,5,FALSE),PV(HLOOKUP(Results!$B$2,Inputs!$B$2:'Inputs'!$L$9,6,FALSE),10,Inputs!$B$22)))/(1-Inputs!$B$23) -> 28.057921 | I3: =((HLOOKUP(Results!$B$2,Inputs!$B$2:$L$11,10,FALSE)/($F3*8760)+I$1/1000)*HLOOKUP(Results!$B$2,Inputs!$B$2:'Inputs'!$L$9,4,FALSE) - PMT(HLOOKUP(Results!$B$2,Inputs!$B$2:'Inputs'!$L$9,6,FALSE),HLOOKUP(Results!$B$2,Inputs!$B$2:'Inputs'!$L$9,5,FALSE),PV(HLOOKUP(Results!$B$2,Inputs!$B$2:'Inputs'!$L$9,6,FALSE),10,Inputs!$B$22)))/(1-Inputs!$B$23) -> 27.557921 | J3: =((HLOOKUP(Results!$B$2,Inputs!$B$2:$L$11,10,FALSE)/($F3*8760)+J$1/1000)*HLOOKUP(Results!$B$2,Inputs!$B$2:'Inputs'!$L$9,4,FALSE) - PMT(HLOOKUP(Results!$B$2,Inputs!$B$2:'Inputs'!$L$9,6,FALSE),HLOOKUP(Results!$B$2,Inputs!$B$2:'Inputs'!$L$9,5,FALSE),PV(HLOOKUP(Results!$B$2,Inputs!$B$2:'Inputs'!$L$9,6,FALSE),10,Inputs!$B$22)))/(1-Inputs!$B$23) -> 27.057921 | K3: =((HLOOKUP(Results!$B$2,Inputs!$B$2:$L$11,10,FALSE)/($F3*8760)+K$1/1000)*HLOOKUP(Results!$B$2,Inputs!$B$2:'Inputs'!$L$9,4,FALSE) - PMT(HLOOKUP(Results!$B$2,Inputs!$B$2:'Inputs'!$L$9,6,FALSE),HLOOKUP(Results!$B$2,Inputs!$B$2:'Inputs'!$L$9,5,FALSE),PV(HLOOKUP(Results!$B$2,Inputs!$B$2:'Inputs'!$L$9,6,FALSE),10,Inputs!$B$22)))/(1-Inputs!$B$23) -> 26.557921 | L3: =((HLOOKUP(Results!$B$2,Inputs!$B$2:$L$11,10,FALSE)/($F3*8760)+L$1/1000)*HLOOKUP(Results!$B$2,Inputs!$B$2:'Inputs'!$L$9,4,FALSE) - PMT(HLOOKUP(Results!$B$2,Inputs!$B$2:'Inputs'!$L$9,6,FALSE),HLOOKUP(Results!$B$2,Inputs!$B$2:'Inputs'!$L$9,5,FALSE),PV(HLOOKUP(Results!$B$2,Inputs!$B$2:'Inputs'!$L$9,6,FALSE),10,Inputs!$B$22)))/(1-Inputs!$B$23) -> 26.057921 | M3: =((HLOOKUP(Results!$B$2,Inputs!$B$2:$L$11,10,FALSE)/($F3*8760)+M$1/1000)*HLOOKUP(Results!$B$2,Inputs!$B$2:'Inputs'!$L$9,4,FALSE) - PMT(HLOOKUP(Results!$B$2,Inputs!$B$2:'Inputs'!$L$9,6,FALSE),HLOOKUP(Results!$B$2,Inputs!$B$2:'Inputs'!$L$9,5,FALSE),PV(HLOOKUP(Results!$B$2,Inputs!$B$2:'Inputs'!$L$9,6,FALSE),10,Inputs!$B$22)))/(1-Inputs!$B$23) -> 25.557921 | AF3: 1 | AG3: =Inputs!$B$24 -> 1.25
A4: Electric Hydrogen | F4: 0.06 | G4: =((HLOOKUP(Results!$B$2,Inputs!$B$2:$L$11,10,FALSE)/($F4*8760)+G$1/1000)*HLOOKUP(Results!$B$2,Inputs!$B$2:'Inputs'!$L$9,4,FALSE) - PMT(HLOOKUP(Results!$B$2,Inputs!$B$2:'Inputs'!$L$9,6,FALSE),HLOOKUP(Results!$B$2,Inputs!$B$2:'Inputs'!$L$9,5,FALSE),PV(HLOOKUP(Results!$B$2,Inputs!$B$2:'Inputs'!$L$9,6,FALSE),10,Inputs!$B$22)))/(1-Inputs!$B$23) -> 19.038614 | H4: =((HLOOKUP(Results!$B$2,Inputs!$B$2:$L$11,10,FALSE)/($F4*8760)+H$1/1000)*HLOOKUP(Results!$B$2,Inputs!$B$2:'Inputs'!$L$9,4,FALSE) - PMT(HLOOKUP(Results!$B$2,Inputs!$B$2:'Inputs'!$L$9,6,FALSE),HLOOKUP(Results!$B$2,Inputs!$B$2:'Inputs'!$L$9,5,FALSE),PV(HLOOKUP(Results!$B$2,Inputs!$B$2:'Inputs'!$L$9,6,FALSE),10,Inputs!$B$22)))/(1-Inputs!$B$23) -> 18.538614 | I4: =((HLOOKUP(Results!$B$2,Inputs!$B$2:$L$11,10,FALSE)/($F4*8760)+I$1/1000)*HLOOKUP(Results!$B$2,Inputs!$B$2:'Inputs'!$L$9,4,FALSE) - PMT(HLOOKUP(Results!$B$2,Inputs!$B$2:'Inputs'!$L$9,6,FALSE),HLOOKUP(Results!$B$2,Inputs!$B$2:'Inputs'!$L$9,5,FALSE),PV(HLOOKUP(Results!$B$2,Inputs!$B$2:'Inputs'!$L$9,6,FALSE),10,Inputs!$B$22)))/(1-Inputs!$B$23) -> 18.038614 | J4: =((HLOOKUP(Results!$B$2,Inputs!$B$2:$L$11,10,FALSE)/($F4*8760)+J$1/1000)*HLOOKUP(Results!$B$2,Inputs!$B$2:'Inputs'!$L$9,4,FALSE) - PMT(HLOOKUP(Results!$B$2,Inputs!$B$2:'Inputs'!$L$9,6,FALSE),HLOOKUP(Results!$B$2,Inputs!$B$2:'Inputs'!$L$9,5,FALSE),PV(HLOOKUP(Results!$B$2,Inputs!$B$2:'Inputs'!$L$9,6,FALSE),10,Inputs!$B$22)))/(1-Inputs!$B$23) -> 17.538614 | K4: =((HLOOKUP(Results!$B$2,Inputs!$B$2:$L$11,10,FALSE)/($F4*8760)+K$1/1000)*HLOOKUP(Results!$B$2,Inputs!$B$2:'Inputs'!$L$9,4,FALSE) - PMT(HLOOKUP(Results!$B$2,Inputs!$B$2:'Inputs'!$L$9,6,FALSE),HLOOKUP(Results!$B$2,Inputs!$B$2:'Inputs'!$L$9,5,FALSE),PV(HLOOKUP(Results!$B$2,Inputs!$B$2:'Inputs'!$L$9,6,FALSE),10,Inputs!$B$22)))/(1-Inputs!$B$23) -> 17.038614 | L4: =((HLOOKUP(Results!$B$2,Inputs!$B$2:$L$11,10,FALSE)/($F4*8760)+L$1/1000)*HLOOKUP(Results!$B$2,Inputs!$B$2:'Inputs'!$L$9,4,FALSE) - PMT(HLOOKUP(Results!$B$2,Inputs!$B$2:'Inputs'!$L$9,6,FALSE),HLOOKUP(Results!$B$2,Inputs!$B$2:'Inputs'!$L$9,5,FALSE),PV(HLOOKUP(Results!$B$2,Inputs!$B$2:'Inputs'!$L$9,6,FALSE),10,Inputs!$B$22)))/(1-Inputs!$B$23) -> 16.538614 | M4: =((HLOOKUP(Results!$B$2,Inputs!$B$2:$L$11,10,FALSE)/($F4*8760)+M$1/1000)*HLOOKUP(Results!$B$2,Inputs!$B$2:'Inputs'!$L$9,4,FALSE) - PMT(HLOOKUP(Results!$B$2,Inputs!$B$2:'Inputs'!$L$9,6,FALSE),HLOOKUP(Results!$B$2,Inputs!$B$2:'Inputs'!$L$9,5,FALSE),PV(HLOOKUP(Results!$B$2,Inputs!$B$2:'Inputs'!$L$9,6,FALSE),10,Inputs!$B$22)))/(1-Inputs!$B$23) -> 16.038614
A5: Energy Innovation LLC | F5: 0.08 | G5: =((HLOOKUP(Results!$B$2,Inputs!$B$2:$L$11,10,FALSE)/($F5*8760)+G$1/1000)*HLOOKUP(Results!$B$2,Inputs!$B$2:'Inputs'!$L$9,4,FALSE) - PMT(HLOOKUP(Results!$B$2,Inputs!$B$2:'Inputs'!$L$9,6,FALSE),HLOOKUP(Results!$B$2,Inputs!$B$2:'Inputs'!$L$9,5,FALSE),PV(HLOOKUP(Results!$B$2,Inputs!$B$2:'Inputs'!$L$9,6,FALSE),10,Inputs!$B$22)))/(1-Inputs!$B$23) -> 14.278961 | H5: =((HLOOKUP(Results!$B$2,Inputs!$B$2:$L$11,10,FALSE)/($F5*8760)+H$1/1000)*HLOOKUP(Results!$B$2,Inputs!$B$2:'Inputs'!$L$9,4,FALSE) - PMT(HLOOKUP(Results!$B$2,Inputs!$B$2:'Inputs'!$L$9,6,FALSE),HLOOKUP(Results!$B$2,Inputs!$B$2:'Inputs'!$L$9,5,FALSE),PV(HLOOKUP(Results!$B$2,Inputs!$B$2:'Inputs'!$L$9,6,FALSE),10,Inputs!$B$22)))/(1-Inputs!$B$23) -> 13.778961 | I5: =((HLOOKUP(Results!$B$2,Inputs!$B$2:$L$11,10,FALSE)/($F5*8760)+I$1/1000)*HLOOKUP(Results!$B$2,Inputs!$B$2:'Inputs'!$L$9,4,FALSE) - PMT(HLOOKUP(Results!$B$2,Inputs!$B$2:'Inputs'!$L$9,6,FALSE),HLOOKUP(Results!$B$2,Inputs!$B$2:'Inputs'!$L$9,5,FALSE),PV(HLOOKUP(Results!$B$2,Inputs!$B$2:'Inputs'!$L$9,6,FALSE),10,Inputs!$B$22)))/(1-Inputs!$B$23) -> 13.278961 | J5: =((HLOOKUP(Results!$B$2,Inputs!$B$2:$L$11,10,FALSE)/($F5*8760)+J$1/1000)*HLOOKUP(Results!$B$2,Inputs!$B$2:'Inputs'!$L$9,4,FALSE) - PMT(HLOOKUP(Results!$B$2,Inputs!$B$2:'Inputs'!$L$9,6,FALSE),HLOOKUP(Results!$B$2,Inputs!$B$2:'Inputs'!$L$9,5,FALSE),PV(HLOOKUP(Results!$B$2,Inputs!$B$2:'Inputs'!$L$9,6,FALSE),10,Inputs!$B$22)))/(1-Inputs!$B$23) -> 12.778961 | K5: =((HLOOKUP(Results!$B$2,Inputs!$B$2:$L$11,10,FALSE)/($F5*8760)+K$1/1000)*HLOOKUP(Results!$B$2,Inputs!$B$2:'Inputs'!$L$9,4,FALSE) - PMT(HLOOKUP(Results!$B$2,Inputs!$B$2:'Inputs'!$L$9,6,FALSE),HLOOKUP(Results!$B$2,Inputs!$B$2:'Inputs'!$L$9,5,FALSE),PV(HLOOKUP(Results!$B$2,Inputs!$B$2:'Inputs'!$L$9,6,FALSE),10,Inputs!$B$22)))/(1-Inputs!$B$23) -> 12.278961 | L5: =((HLOOKUP(Results!$B$2,Inputs!$B$2:$L$11,10,FALSE)/($F5*8760)+L$1/1000)*HLOOKUP(Results!$B$2,Inputs!$B$2:'Inputs'!$L$9,4,FALSE) - PMT(HLOOKUP(Results!$B$2,Inputs!$B$2:'Inputs'!$L$9,6,FALSE),HLOOKUP(Results!$B$2,Inputs!$B$2:'Inputs'!$L$9,5,FALSE),PV(HLOOKUP(Results!$B$2,Inputs!$B$2:'Inputs'!$L$9,6,FALSE),10,Inputs!$B$22)))/(1-Inputs!$B$23) -> 11.778961 | M5: =((HLOOKUP(Results!$B$2,Inputs!$B$2:$L$11,10,FALSE)/($F5*8760)+M$1/1000)*HLOOKUP(Results!$B$2,Inputs!$B$2:'Inputs'!$L$9,4,FALSE) - PMT(HLOOKUP(Results!$B$2,Inputs!$B$2:'Inputs'!$L$9,6,FALSE),HLOOKUP(Results!$B$2,Inputs!$B$2:'Inputs'!$L$9,5,FALSE),PV(HLOOKUP(Results!$B$2,Inputs!$B$2:'Inputs'!$L$9,6,FALSE),10,Inputs!$B$22)))/(1-Inputs!$B$23) -> 11.278961
A6: Clean Energy Developer 1 | F6: 0.1 | G6: =((HLOOKUP(Results!$B$2,Inputs!$B$2:$L$11,10,FALSE)/($F6*8760)+G$1/1000)*HLOOKUP(Results!$B$2,Inputs!$B$2:'Inputs'!$L$9,4,FALSE) - PMT(HLOOKUP(Results!$B$2,Inputs!$B$2:'Inputs'!$L$9,6,FALSE),HLOOKUP(Results!$B$2,Inputs!$B$2:'Inputs'!$L$9,5,FALSE),PV(HLOOKUP(Results!$B$2,Inputs!$B$2:'Inputs'!$L$9,6,FALSE),10,Inputs!$B$22)))/(1-Inputs!$B$23) -> 11.423168 | H6: =((HLOOKUP(Results!$B$2,Inputs!$B$2:$L$11,10,FALSE)/($F6*8760)+H$1/1000)*HLOOKUP(Results!$B$2,Inputs!$B$2:'Inputs'!$L$9,4,FALSE) - PMT(HLOOKUP(Results!$B$2,Inputs!$B$2:'Inputs'!$L$9,6,FALSE),HLOOKUP(Results!$B$2,Inputs!$B$2:'Inputs'!$L$9,5,FALSE),PV(HLOOKUP(Results!$B$2,Inputs!$B$2:'Inputs'!$L$9,6,FALSE),10,Inputs!$B$22)))/(1-Inputs!$B$23) -> 10.923168 | I6: =((HLOOKUP(Results!$B$2,Inputs!$B$2:$L$11,10,FALSE)/($F6*8760)+I$1/1000)*HLOOKUP(Results!$B$2,Inputs!$B$2:'Inputs'!$L$9,4,FALSE) - PMT(HLOOKUP(Results!$B$2,Inputs!$B$2:'Inputs'!$L$9,6,FALSE),HLOOKUP(Results!$B$2,Inputs!$B$2:'Inputs'!$L$9,5,FALSE),PV(HLOOKUP(Results!$B$2,Inputs!$B$2:'Inputs'!$L$9,6,FALSE),10,Inputs!$B$22)))/(1-Inputs!$B$23) -> 10.423168 | J6: =((HLOOKUP(Results!$B$2,Inputs!$B$2:$L$11,10,FALSE)/($F6*8760)+J$1/1000)*HLOOKUP(Results!$B$2,Inputs!$B$2:'Inputs'!$L$9,4,FALSE) - PMT(HLOOKUP(Results!$B$2,Inputs!$B$2:'Inputs'!$L$9,6,FALSE),HLOOKUP(Results!$B$2,Inputs!$B$2:'Inputs'!$L$9,5,FALSE),PV(HLOOKUP(Results!$B$2,Inputs!$B$2:'Inputs'!$L$9,6,FALSE),10,Inputs!$B$22)))/(1-Inputs!$B$23) -> 9.9231685 | K6: =((HLOOKUP(Results!$B$2,Inputs!$B$2:$L$11,10,FALSE)/($F6*8760)+K$1/1000)*HLOOKUP(Results!$B$2,Inputs!$B$2:'Inputs'!$L$9,4,FALSE) - PMT(HLOOKUP(Results!$B$2,Inputs!$B$2:'Inputs'!$L$9,6,FALSE),HLOOKUP(Results!$B$2,Inputs!$B$2:'Inputs'!$L$9,5,FALSE),PV(HLOOKUP(Results!$B$2,Inputs!$B$2:'Inputs'!$L$9,6,FALSE),10,Inputs!$B$22)))/(1-Inputs!$B$23) -> 9.4231685 | L6: =((HLOOKUP(Results!$B$2,Inputs!$B$2:$L$11,10,FALSE)/($F6*8760)+L$1/1000)*HLOOKUP(Results!$B$2,Inputs!$B$2:'Inputs'!$L$9,4,FALSE) - PMT(HLOOKUP(Results!$B$2,Inputs!$B$2:'Inputs'!$L$9,6,FALSE),HLOOKUP(Results!$B$2,Inputs!$B$2:'Inputs'!$L$9,5,FALSE),PV(HLOOKUP(Results!$B$2,Inputs!$B$2:'Inputs'!$L$9,6,FALSE),10,Inputs!$B$22)))/(1-Inputs!$B$23) -> 8.9231685 | M6: =((HLOOKUP(Results!$B$2,Inputs!$B$2:$L$11,10,FALSE)/($F6*8760)+M$1/1000)*HLOOKUP(Results!$B$2,Inputs!$B$2:'Inputs'!$L$9,4,FALSE) - PMT(HLOOKUP(Results!$B$2,Inputs!$B$2:'Inputs'!$L$9,6,FALSE),HLOOKUP(Results!$B$2,Inputs!$B$2:'Inputs'!$L$9,5,FALSE),PV(HLOOKUP(Results!$B$2,Inputs!$B$2:'Inputs'!$L$9,6,FALSE),10,Inputs!$B$22)))/(1-Inputs!$B$23) -> 8.4231685
A7: Clean Energy Developer 2 | F7: 0.12 | G7: =((HLOOKUP(Results!$B$2,Inputs!$B$2:$L$11,10,FALSE)/($F7*8760)+G$1/1000)*HLOOKUP(Results!$B$2,Inputs!$B$2:'Inputs'!$L$9,4,FALSE) - PMT(HLOOKUP(Results!$B$2,Inputs!$B$2:'Inputs'!$L$9,6,FALSE),HLOOKUP(Results!$B$2,Inputs!$B$2:'Inputs'!$L$9,5,FALSE),PV(HLOOKUP(Results!$B$2,Inputs!$B$2:'Inputs'!$L$9,6,FALSE),10,Inputs!$B$22)))/(1-Inputs!$B$23) -> 9.5193071 | H7: =((HLOOKUP(Results!$B$2,Inputs!$B$2:$L$11,10,FALSE)/($F7*8760)+H$1/1000)*HLOOKUP(Results!$B$2,Inputs!$B$2:'Inputs'!$L$9,4,FALSE) - PMT(HLOOKUP(Results!$B$2,Inputs!$B$2:'Inputs'!$L$9,6,FALSE),HLOOKUP(Results!$B$2,Inputs!$B$2:'Inputs'!$L$9,5,FALSE),PV(HLOOKUP(Results!$B$2,Inputs!$B$2:'Inputs'!$L$9,6,FALSE),10,Inputs!$B$22)))/(1-Inputs!$B$23) -> 9.0193071 | I7: =((HLOOKUP(Results!$B$2,Inputs!$B$2:$L$11,10,FALSE)/($F7*8760)+I$1/1000)*HLOOKUP(Results!$B$2,Inputs!$B$2:'Inputs'!$L$9,4,FALSE) - PMT(HLOOKUP(Results!$B$2,Inputs!$B$2:'Inputs'!$L$9,6,FALSE),HLOOKUP(Results!$B$2,Inputs!$B$2:'Inputs'!$L$9,5,FALSE),PV(HLOOKUP(Results!$B$2,Inputs!$B$2:'Inputs'!$L$9,6,FALSE),10,Inputs!$B$22)))/(1-Inputs!$B$23) -> 8.5193071 | J7: =((HLOOKUP(Results!$B$2,Inputs!$B$2:$L$11,10,FALSE)/($F7*8760)+J$1/1000)*HLOOKUP(Results!$B$2,Inputs!$B$2:'Inputs'!$L$9,4,FALSE) - PMT(HLOOKUP(Results!$B$2,Inputs!$B$2:'Inputs'!$L$9,6,FALSE),HLOOKUP(Results!$B$2,Inputs!$B$2:'Inputs'!$L$9,5,FALSE),PV(HLOOKUP(Results!$B$2,Inputs!$B$2:'Inputs'!$L$9,6,FALSE),10,Inputs!$B$22)))/(1-Inputs!$B$23) -> 8.0193071 | K7: =((HLOOKUP(Results!$B$2,Inputs!$B$2:$L$11,10,FALSE)/($F7*8760)+K$1/1000)*HLOOKUP(Results!$B$2,Inputs!$B$2:'Inputs'!$L$9,4,FALSE) - PMT(HLOOKUP(Results!$B$2,Inputs!$B$2:'Inputs'!$L$9,6,FALSE),HLOOKUP(Results!$B$2,Inputs!$B$2:'Inputs'!$L$9,5,FALSE),PV(HLOOKUP(Results!$B$2,Inputs!$B$2:'Inputs'!$L$9,6,FALSE),10,Inputs!$B$22)))/(1-Inputs!$B$23) -> 7.5193071 | L7: =((HLOOKUP(Results!$B$2,Inputs!$B$2:$L$11,10,FALSE)/($F7*8760)+L$1/1000)*HLOOKUP(Results!$B$2,Inputs!$B$2:'Inputs'!$L$9,4,FALSE) - PMT(HLOOKUP(Results!$B$2,Inputs!$B$2:'Inputs'!$L$9,6,FALSE),HLOOKUP(Results!$B$2,Inputs!$B$2:'Inputs'!$L$9,5,FALSE),PV(HLOOKUP(Results!$B$2,Inputs!$B$2:'Inputs'!$L$9,6,FALSE),10,Inputs!$B$22)))/(1-Inputs!$B$23) -> 7.0193071 | M7: =((HLOOKUP(Results!$B$2,Inputs!$B$2:$L$11,10,FALSE)/($F7*8760)+M$1/1000)*HLOOKUP(Results!$B$2,Inputs!$B$2:'Inputs'!$L$9,4,FALSE) - PMT(HLOOKUP(Results!$B$2,Inputs!$B$2:'Inputs'!$L$9,6,FALSE),HLOOKUP(Results!$B$2,Inputs!$B$2:'Inputs'!$L$9,5,FALSE),PV(HLOOKUP(Results!$B$2,Inputs!$B$2:'Inputs'!$L$9,6,FALSE),10,Inputs!$B$22)))/(1-Inputs!$B$23) -> 6.5193071
A8: Rhodium Group | F8: 0.14 | G8: =((HLOOKUP(Results!$B$2,Inputs!$B$2:$L$11,10,FALSE)/($F8*8760)+G$1/1000)*HLOOKUP(Results!$B$2,Inputs!$B$2:'Inputs'!$L$9,4,FALSE) - PMT(HLOOKUP(Results!$B$2,Inputs!$B$2:'Inputs'!$L$9,6,FALSE),HLOOKUP(Results!$B$2,Inputs!$B$2:'Inputs'!$L$9,5,FALSE),PV(HLOOKUP(Results!$B$2,Inputs!$B$2:'Inputs'!$L$9,6,FALSE),10,Inputs!$B$22)))/(1-Inputs!$B$23) -> 8.1594061 | H8: =((HLOOKUP(Results!$B$2,Inputs!$B$2:$L$11,10,FALSE)/($F8*8760)+H$1/1000)*HLOOKUP(Results!$B$2,Inputs!$B$2:'Inputs'!$L$9,4,FALSE) - PMT(HLOOKUP(Results!$B$2,Inputs!$B$2:'Inputs'!$L$9,6,FALSE),HLOOKUP(Results!$B$2,Inputs!$B$2:'Inputs'!$L$9,5,FALSE),PV(HLOOKUP(Results!$B$2,Inputs!$B$2:'Inputs'!$L$9,6,FALSE),10,Inputs!$B$22)))/(1-Inputs!$B$23) -> 7.6594061 | I8: =((HLOOKUP(Results!$B$2,Inputs!$B$2:$L$11,10,FALSE)/($F8*8760)+I$1/1000)*HLOOKUP(Results!$B$2,Inputs!$B$2:'Inputs'!$L$9,4,FALSE) - PMT(HLOOKUP(Results!$B$2,Inputs!$B$2:'Inputs'!$L$9,6,FALSE),HLOOKUP(Results!$B$2,Inputs!$B$2:'Inputs'!$L$9,5,FALSE),PV(HLOOKUP(Results!$B$2,Inputs!$B$2:'Inputs'!$L$9,6,FALSE),10,Inputs!$B$22)))/(1-Inputs!$B$23) -> 7.1594061 | J8: =((HLOOKUP(Results!$B$2,Inputs!$B$2:$L$11,10,FALSE)/($F8*8760)+J$1/1000)*HLOOKUP(Results!$B$2,Inputs!$B$2:'Inputs'!$L$9,4,FALSE) - PMT(HLOOKUP(Results!$B$2,Inputs!$B$2:'Inputs'!$L$9,6,FALSE),HLOOKUP(Results!$B$2,Inputs!$B$2:'Inputs'!$L$9,5,FALSE),PV(HLOOKUP(Results!$B$2,Inputs!$B$2:'Inputs'!$L$9,6,FALSE),10,Inputs!$B$22)))/(1-Inputs!$B$23) -> 6.6594061 | K8: =((HLOOKUP(Results!$B$2,Inputs!$B$2:$L$11,10,FALSE)/($F8*8760)+K$1/1000)*HLOOKUP(Results!$B$2,Inputs!$B$2:'Inputs'!$L$9,4,FALSE) - PMT(HLOOKUP(Results!$B$2,Inputs!$B$2:'Inputs'!$L$9,6,FALSE),HLOOKUP(Results!$B$2,Inputs!$B$2:'Inputs'!$L$9,5,FALSE),PV(HLOOKUP(Results!$B$2,Inputs!$B$2:'Inputs'!$L$9,6,FALSE),10,Inputs!$B$22)))/(1-Inputs!$B$23) -> 6.1594061 | L8: =((HLOOKUP(Results!$B$2,Inputs!$B$2:$L$11,10,FALSE)/($F8*8760)+L$1/1000)*HLOOKUP(Results!$B$2,Inputs!$B$2:'Inputs'!$L$9,4,FALSE) - PMT(HLOOKUP(Results!$B$2,Inputs!$B$2:'Inputs'!$L$9,6,FALSE),HLOOKUP(Results!$B$2,Inputs!$B$2:'Inputs'!$L$9,5,FALSE),PV(HLOOKUP(Results!$B$2,Inputs!$B$2:'Inputs'!$L$9,6,FALSE),10,Inputs!$B$22)))/(1-Inputs!$B$23) -> 5.6594061 | M8: =((HLOOKUP(Results!$B$2,Inputs!$B$2:$L$11,10,FALSE)/($F8*8760)+M$1/1000)*HLOOKUP(Results!$B$2,Inputs!$B$2:'Inputs'!$L$9,4,FALSE) - PMT(HLOOKUP(Results!$B$2,Inputs!$B$2:'Inputs'!$L$9,6,FALSE),HLOOKUP(Results!$B$2,Inputs!$B$2:'Inputs'!$L$9,5,FALSE),PV(HLOOKUP(Results!$B$2,Inputs!$B$2:'Inputs'!$L$9,6,FALSE),10,Inputs!$B$22)))/(1-Inputs!$B$23) -> 5.1594061
