Workbook
Name ox_000028bb_90d5_5dec_9cc8_870a93150530: 'Use Phase_Grid'!$R$140
Name ox_0001a265_7c13_5323_a99e_9642e264d6d6: Graphs!$B$62
Name ox_0002fcf0_4b0e_56b6_98d4_b9da58e42647: Recycling!$AU$313
Name ox_0003f549_bfde_59b1_a952_f0de26d8c51c: 'Use Phase'!$S$305
Name ox_0006e781_1fd8_50bf_81b1_ab22c72202cd: Resume_SensAnal!$D$36
Name ox_000cd5fc_e2c5_5040_b3de_f4248a2188ff: 'Heat map article'!$AQ$34
Name ox_000cfc63_95aa_5e42_8ce2_48abdb5c9257: 'Use Phase'!$M$393
Name ox_0010c928_8eed_51b1_91b3_ae52a8840e5d: 'Heat map article'!$AS$26
Name ox_0010cf07_9393_5c68_a2cc_2fd3c29159e0: Recycling!$BJ$331
Name ox_0017412b_887d_5889_9666_6fb17dbfead4: 'Use Phase_Grid'!$N$160
Name ox_002037de_57c0_53b2_aacf_ecf8d9a0a688: Resume_SensAnal!$I$154
Name ox_002c3543_07be_539b_a45d_94d73b645510: 'Use Phase_Grid'!$L$240
Name ox_003765ed_e390_5429_9739_27dce258ec6c: Resume_SensAnal!$J$173
Name ox_00387ac0_2f2e_5ef6_b125_9e2552124283: Production!$F$118
Name ox_00389837_6880_55b2_947e_77246a7205dd: Resume_SensAnal!$AR$94
Name ox_00393b89_70de_570e_93b8_669e8395f382: Recycling!$F$179
Name ox_003977ab_1df7_5c21_9841_364569dae4fb: Production!$BM$92
Name ox_003adf5e_00f6_5a4a_ac90_6d30b9f5cea7: Production!$F$111
Name ox_003c9efc_36cd_5352_8a1c_0e1fc5d0565b: Resume_SensAnal!$M$62
Name ox_00403999_e507_55be_97b0_92e7b9fa2a77: Production!$M$172
Name ox_0041e06d_5458_5978_afea_bebdb0a51d98: 'Heat map article'!$AM$19
Name ox_0042c04e_c204_500e_b95a_0f74727157bf: Resume_SensAnal!$E$88
Name ox_0044aedb_e399_55d5_b7a7_6a1fdac0e874: 'Heat map article'!$AJ$20
Name ox_00467b8b_0a17_5dc0_a333_d0efd6c7742e: Recycling!$R$123
Name ox_004e0a9e_214c_5848_a337_a073fdd0d51f: Resume_SensAnal!$M$161
Name ox_0051cc7c_41b0_5e22_bb05_d40e43990d73: Resume_SensAnal!$T$195
Name ox_0055de65_0f23_53bc_bce6_dc2457d38095: 'Use Phase'!$N$168
Name ox_00560a69_1309_5dd8_87b4_d9c214d4a616: Production!$Q$55
Name ox_005628c3_7fa4_5ed2_b045_c66a3234e2e6: 'Use Phase'!$AL$190
Name ox_00572e3e_50d9_57ed_b814_bd3bf802fd8c: Resume_SensAnal!$R$207
Name ox_005ca4dc_5160_5391_bc76_a50a3436a749: 'Use Phase'!$AJ$146
Name ox_005d2343_c0e2_5b8a_9eaa_8f0aa563b004: Graphs!$B$24
Name ox_0062fee3_6d9f_5943_b9c5_b9d933c35db0: 'Use Phase'!$O$198
Name ox_006543d9_f414_598f_bb8d_ac556739ac29: Recycling!$J$112
Name ox_006924fb_4d08_5831_b8fc_77302473a9a6: Production!$BN$206
Name ox_006da381_641b_5db9_905e_e0ea1179c805: Graphs!$B$63
Name ox_0072f0f6_3693_5fd6_871f_263e47a7271d: 'Use Phase'!$AE$286
Name ox_0074d227_9769_519b_993e_0ab5cc5f2384: 'Use Phase'!$W$190
Name ox_007652c8_23ec_518b_81b8_f2338f55872d: Resume_SensAnal!$M$149
Name ox_007a4e90_cb4c_5df4_aaeb_c52e624a697a: Resume_SensAnal!$V$187
Name ox_00816759_0d72_5b44_92b5_7d85e1375975: Recycling!$AU$315
Name ox_0084f91a_7382_5864_be40_1a93498978be: 'Use Phase'!$L$63
Name ox_00872e58_aefc_5b92_8ccd_780cee191c3c: 'Use Phase'!$N$210
Name ox_00891f92_f1e2_5fdf_aad1_224b4b17a67e: Recycling!$BK$306
Name ox_008c1580_41f1_5e31_86d5_4710ab21e4d0: Recycling!$I$104
Name ox_008c771b_59a0_5ff6_8ba1_9d6cf9d5687c: Recycling!$AO$105
Name ox_008f6c45_d8a6_51c3_9c57_cbaed3a23bfb: 'Use Phase'!$W$265
Name ox_00963417_c512_55c2_a27d_b5a9031629dd: Recycling!$AW$127
Name ox_0098ea5a_c149_5c99_998a_c122b3fd976e: 'Use Phase_Grid'!$N$91
Name ox_009a923c_9fc8_59e2_be49_7c89a1f39370: 'Use Phase'!$AJ$201
Name ox_009bb2c3_b15f_54b4_94bf_7e2d092b76a1: 'Use Phase_Grid'!$J$96
Name ox_009bf130_7eae_532f_9e5f_b0be0d86de47: 'Use Phase'!$K$308
Name ox_009dcafc_2525_5cac_a87f_f6051520709b: Resume_SensAnal!$P$210
Name ox_00a189fb_09d2_5130_8c93_f78bad16ac68: 'Use Phase'!$T$276
Name ox_00a250d7_b7fa_52d4_aefd_76996a6ffd92: 'Heat map article'!$I$6
Name ox_00a27ac3_f051_512c_95aa_ec8cb1b46eec: Production!$H$151
Name ox_00a50a65_28c1_5039_807c_5e4e3086ee8c: 'Use Phase_Grid'!$K$72
Name ox_00a54843_45e7_5c5f_bcb7_0b10fa048cd4: 'Heat map article'!$L$44
Name ox_00a8226e_bc51_5824_a703_5b1eddb6f799: Resume_SensAnal!$K$91
Name ox_00ac22cf_7dba_5121_82bc_7b15930b2f85: Recycling!$BX$103

Sheet Cover
B2: SUPPLEMENTARY INFORMATION
B4: On the environmental competitiveness of Sodium-Ion batteries under a full life cycle perspective – A cell-chemistry specific modelling approach
B5: Jens F. Petersa,b*, Manuel Baumannc, Joachim Binderd, Marcel Weilc,e
B7: aUniversity of Alcalá (UAH), Department of Economics, Alcalá de Henares, Madrid, Spain
B8: bIMDEA Energy, Systems Analysis Unit, Móstoles, Madrid, Spain
B9: cInstitute for Technology Assessment and System Analysis (ITAS), Karlsruhe Institute of Technology (KIT), Germany.
B10: dInstitute for Applied Materials (IAM-ESS), Karlsruhe Institute of Technology (KIT), Germany.
B11: eHelmholtz Institute Ulm for Electrochemical Energy Storage (HIU), Ulm, Germany
B15: This spreadsheet contains all results tables and the underlying calculations for reproducing the Figures and Results presented in the main manuscript
B17: All data is published under CC-BY license and free for re-use, as long as the source is properly cited.

Sheet Production
B1: Na-Ion battery cell, prismatic, Na-NMC(111)-HC (2021) | G1: re-calculated with updated LCU (19.07.) | L1: Na-Ion battery cell, prismatic, NaMVP-HC (2021) | V1: Na-Ion battery cell, prismatic, NaMMO-HC (2021) | AA1: re-calculated with updated LCI (19.07.) | AF1: Na-Ion battery cell, prismatic, NaNMMT (2021) | AK1: LCI unchanged (19.7.) | AP1: Na-Ion battery cell, prismatic, NaPBA-HC (2021) | AZ1: Li-Ion battery cell, prismatic, NMC622-C (2021) | BE1: LCI unchanged (19.7.) | BJ1: Li-Ion battery cell, prismatic, LFP-C (2021) | BN1: LCI unchanged (19.7.)
B2: 1161.45 g Na-Ion battery cell, prismatic, NMC-HC (2021) | L2: 1039.4 g Na-Ion battery cell, prismatic, NaMVP-HC (2021) | V2: 1007.7 g Na-Ion battery cell, prismatic, NaMMO-HC (2021) | AF2: 921.64 kg Na-Ion battery cell, prismatic, NMMT-HC (2021) | AZ2: 600.29 kg Li-Ion battery cell, prismatic, NMC622-C (2021) | BJ2: 800.13 kg Li-Ion battery cell, prismatic, LFP-C (2021)
B3: Impact analysis | E3: =B1 -> Na-Ion battery cell, prismatic, Na-NMC(111)-HC (2021) | L3: =B3 -> Impact analysis | O3: =L1 -> Na-Ion battery cell, prismatic, NaMVP-HC (2021) | V3: =L3 -> Impact analysis | Y3: =V1 -> Na-Ion battery cell, prismatic, NaMMO-HC (2021) | AF3: =V3 -> Impact analysis | AI3: =AF1 -> Na-Ion battery cell, prismatic, NaNMMT (2021) | AP3: =AF3 -> Impact analysis | AS3: =AP1 -> Na-Ion battery cell, prismatic, NaPBA-HC (2021) | AZ3: =AP3 -> Impact analysis | BC3: =AZ1 -> Li-Ion battery cell, prismatic, NMC622-C (2021) | BJ3: =AP3 -> Impact analysis | BM3: =BJ1 -> Li-Ion battery cell, prismatic, LFP-C (2021)
B4: Name | C4: Category | D4: Inventory result | E4: Unit | F4: Impact factor | G4: Unit | H4: Impact result | I4: Unit | L4: Name | M4: Category | N4: Inventory result | O4: Unit | P4: Impact factor | Q4: Unit | R4: Impact result | S4: Unit | V4: Name | W4: Category | X4: Inventory result | Y4: Unit | Z4: Impact factor | AA4: Unit | AB4: Impact result | AC4: Unit | AF4: Name | AG4: Category | AH4: Inventory result | AI4: Unit | AJ4: Impact factor | AK4: Unit | AL4: Impact result | AM4: Unit | AP4: Name | AQ4: Category | AR4: Inventory result | AS4: Unit | AT4: Impact factor | AU4: Unit | AV4: Impact result | AW4: Unit | AZ4: Name | BA4: Category | BB4: Inventory result | BC4: Unit | BD4: Impact factor | BE4: Unit | BF4: Impact result | BG4: Unit | BJ4: Name | BK4: Category | BL4: Inventory result | BM4: Unit | BN4: Impact factor | BO4: Unit | BP4: Impact result | BQ4: Unit
B5: Acidification | H5: 0.15678 | I5: molc H+ eq | L5: Acidification | R5: 0.13554 | S5: molc H+ eq | V5: Acidification | AB5: 0.07892 | AC5: molc H+ eq | AF5: Acidification | AL5: 0.08394 | AM5: molc H+ eq | AP5: Acidification | AV5: 0.09139 | AW5: molc H+ eq | AZ5: Acidification | BF5: 0.07144 | BG5: molc H+ eq | BJ5: Acidification | BP5: 0.05301 | BQ5: molc H+ eq
B6: Climate change | H6: 13.71866 | I6: kg CO2 eq | L6: Climate change | R6: 14.20745 | S6: kg CO2 eq | V6: Climate change | AB6: 8.28422 | AC6: kg CO2 eq | AF6: Climate change | AL6: 8.01709 | AM6: kg CO2 eq | AP6: Climate change | AV6: 13.87795 | AW6: kg CO2 eq | AZ6: Climate change | BF6: 7.10008 | BG6: kg CO2 eq | BJ6: Climate change | BP6: 7.83497 | BQ6: kg CO2 eq
B7: Freshwater ecotoxicity | H7: 549.87634 | I7: CTUe | L7: Freshwater ecotoxicity | R7: 376.75458 | S7: CTUe | V7: Freshwater ecotoxicity | AB7: 123.10079 | AC7: CTUe | AF7: Freshwater ecotoxicity | AL7: 203.26992 | AM7: CTUe | AP7: Freshwater ecotoxicity | AV7: 208.92841 | AW7: CTUe | AZ7: Freshwater ecotoxicity | BF7: 969.27582 | BG7: CTUe | BJ7: Freshwater ecotoxicity | BP7: 1256.8352 | BQ7: CTUe
B8: Freshwater eutrophication | H8: 0.00493 | I8: kg P eq | L8: Freshwater eutrophication | R8: 0.00581 | S8: kg P eq | V8: Freshwater eutrophication | AB8: 0.00278 | AC8: kg P eq | AF8: Freshwater eutrophication | AL8: 0.0026 | AM8: kg P eq | AP8: Freshwater eutrophication | AV8: 0.00398 | AW8: kg P eq | AZ8: Freshwater eutrophication | BF8: 0.00541 | BG8: kg P eq | BJ8: Freshwater eutrophication | BP8: 0.01107 | BQ8: kg P eq
B9: Human toxicity, cancer effects | H9: 6.16316e-06 | I9: CTUh | L9: Human toxicity, cancer effects | R9: 1.50774e-05 | S9: CTUh | U9: =R9+Recycling!R108 -> 1.4671644e-05 | V9: Human toxicity, cancer effects | AB9: 9.65025e-07 | AC9: CTUh | AF9: Human toxicity, cancer effects | AL9: 1.62113e-06 | AM9: CTUh | AP9: Human toxicity, cancer effects | AV9: 1.6302e-06 | AW9: CTUh | AZ9: Human toxicity, cancer effects | BF9: 3.32929e-06 | BG9: CTUh | BJ9: Human toxicity, cancer effects | BP9: 1.92396e-06 | BQ9: CTUh
B10: Human toxicity, non-cancer effects | H10: 1.21864e-05 | I10: CTUh | L10: Human toxicity, non-cancer effects | R10: 1.25432e-05 | S10: CTUh | U10: =R10+Recycling!R109 -> 1.2275196e-05 | V10: Human toxicity, non-cancer effects | AB10: 1.78457e-06 | AC10: CTUh | AF10: Human toxicity, non-cancer effects | AL10: 3.04604e-06 | AM10: CTUh | AP10: Human toxicity, non-cancer effects | AV10: 2.6951e-06 | AW10: CTUh | AZ10: Human toxicity, non-cancer effects | BF10: 1.31593e-05 | BG10: CTUh | BJ10: Human toxicity, non-cancer effects | BP10: 1.38529e-05 | BQ10: CTUh
B11: Ionizing radiation E (interim) | H11: 2.5135e-05 | I11: CTUe | L11: Ionizing radiation E (interim) | R11: 4.72612e-06 | S11: CTUe | T11: =SUM(R9:R10) -> 2.76206e-05 | U11: =SUM(U9:U10) -> 2.694684e-05 | V11: Ionizing radiation E (interim) | AB11: 3.55227e-06 | AC11: CTUe | AF11: Ionizing radiation E (interim) | AL11: 5.73509e-06 | AM11: CTUe | AP11: Ionizing radiation E (interim) | AV11: 4.45032e-06 | AW11: CTUe | AZ11: Ionizing radiation E (interim) | BF11: 1.16005e-05 | BG11: CTUe | BJ11: Ionizing radiation E (interim) | BP11: 2.77624e-06 | BQ11: CTUe
B12: Ionizing radiation HH | H12: 4.11443 | I12: kBq U235 eq | L12: Ionizing radiation HH | R12: 1.43068 | S12: kBq U235 eq | V12: Ionizing radiation HH | AB12: 1.17758 | AC12: kBq U235 eq | AF12: Ionizing radiation HH | AL12: 1.32416 | AM12: kBq U235 eq | AP12: Ionizing radiation HH | AV12: 1.4781 | AW12: kBq U235 eq | AZ12: Ionizing radiation HH | BF12: 1.92503 | BG12: kBq U235 eq | BJ12: Ionizing radiation HH | BP12: 0.86619 | BQ12: kBq U235 eq
B13: Land use | H13: 15.01635 | I13: kg C deficit | L13: Land use | R13: 18.49076 | S13: kg C deficit | V13: Land use | AB13: 9.26896 | AC13: kg C deficit | AF13: Land use | AL13: 11.36192 | AM13: kg C deficit | AP13: Land use | AV13: 12.28548 | AW13: kg C deficit | AZ13: Land use | BF13: 1.84147 | BG13: kg C deficit | BJ13: Land use | BP13: 1.90522 | BQ13: kg C deficit
B14: Marine eutrophication | H14: 0.02472 | I14: kg N eq | L14: Marine eutrophication | R14: 0.02029 | S14: kg N eq | V14: Marine eutrophication | AB14: 0.01545 | AC14: kg N eq | AF14: Marine eutrophication | AL14: 0.01576 | AM14: kg N eq | AP14: Marine eutrophication | AV14: 0.01908 | AW14: kg N eq | AZ14: Marine eutrophication | BF14: 0.0099 | BG14: kg N eq | BJ14: Marine eutrophication | BP14: 0.00984 | BQ14: kg N eq
B15: Mineral, fossil & ren resource depletion | H15: 0.00573 | I15: kg Sb eq | L15: Mineral, fossil & ren resource depletion | R15: 0.00124 | S15: kg Sb eq | V15: Mineral, fossil & ren resource depletion | AB15: 0.00084 | AC15: kg Sb eq | AF15: Mineral, fossil & ren resource depletion | AL15: 0.00144 | AM15: kg Sb eq | AP15: Mineral, fossil & ren resource depletion | AV15: 0.00128 | AW15: kg Sb eq | AZ15: Mineral, fossil & ren resource depletion | BF15: 0.00503 | BG15: kg Sb eq | BJ15: Mineral, fossil & ren resource depletion | BP15: 0.00486 | BQ15: kg Sb eq
B16: Ozone depletion | H16: 1.8274e-06 | I16: kg CFC-11 eq | L16: Ozone depletion | R16: 1.23342e-06 | S16: kg CFC-11 eq | V16: Ozone depletion | AB16: 7.39456e-07 | AC16: kg CFC-11 eq | AF16: Ozone depletion | AL16: 7.37173e-07 | AM16: kg CFC-11 eq | AP16: Ozone depletion | AV16: 1.41684e-06 | AW16: kg CFC-11 eq | AZ16: Ozone depletion | BF16: 7.8499e-07 | BG16: kg CFC-11 eq | BJ16: Ozone depletion | BP16: 6.17554e-07 | BQ16: kg CFC-11 eq
B17: Particulate matter | H17: 0.01158 | I17: kg PM2.5 eq | L17: Particulate matter | R17: 0.0106 | S17: kg PM2.5 eq | V17: Particulate matter | AB17: 0.00658 | AC17: kg PM2.5 eq | AF17: Particulate matter | AL17: 0.00562 | AM17: kg PM2.5 eq | AP17: Particulate matter | AV17: 0.00758 | AW17: kg PM2.5 eq | AZ17: Particulate matter | BF17: 0.00646 | BG17: kg PM2.5 eq | BJ17: Particulate matter | BP17: 0.00557 | BQ17: kg PM2.5 eq
B18: Photochemical ozone formation | H18: 0.05783 | I18: kg NMVOC eq | L18: Photochemical ozone formation | R18: 0.05802 | S18: kg NMVOC eq | V18: Photochemical ozone formation | AB18: 0.03632 | AC18: kg NMVOC eq | AF18: Photochemical ozone formation | AL18: 0.03502 | AM18: kg NMVOC eq | AP18: Photochemical ozone formation | AV18: 0.04534 | AW18: kg NMVOC eq | AZ18: Photochemical ozone formation | BF18: 0.02705 | BG18: kg NMVOC eq | BJ18: Photochemical ozone formation | BP18: 0.02767 | BQ18: kg NMVOC eq
B19: Terrestrial eutrophication | H19: 0.22917 | I19: molc N eq | L19: Terrestrial eutrophication | R19: 0.20654 | S19: molc N eq | V19: Terrestrial eutrophication | AB19: 0.16694 | AC19: molc N eq | AF19: Terrestrial eutrophication | AL19: 0.154 | AM19: molc N eq | AP19: Terrestrial eutrophication | AV19: 0.19186 | AW19: molc N eq | AZ19: Terrestrial eutrophication | BF19: 0.09109 | BG19: molc N eq | BJ19: Terrestrial eutrophication | BP19: 0.10404 | BQ19: molc N eq
B20: Water resource depletion | H20: 15.68326 | I20: m3 water eq | L20: Water resource depletion | R20: 6.97262 | S20: m3 water eq | V20: Water resource depletion | AB20: 5.00015 | AC20: m3 water eq | AF20: Water resource depletion | AL20: 5.58113 | AM20: m3 water eq | AP20: Water resource depletion | AV20: 7.6298 | AW20: m3 water eq | AZ20: Water resource depletion | BF20: 8.01798 | BG20: m3 water eq | BJ20: Water resource depletion | BP20: 4.95109 | BQ20: m3 water eq
B22: energy density | C22: 136.31 | D22: 152.46717 | E22: 157.08 | F22: 171.91013 | G22: 124.1 | H22: 272.11478 | I22: 197.41872 | J22: Wh/kg
B23: capacity (Wh/cell) | C23: 158.31754 | D23: 158.47438 | E23: 158.29108 | F23: 158.44307 | G23: 159.43 | H23: 158.46821 | I23: 157.997 | K23: =B23 -> capacity (Wh/cell) | L23: =C23 -> 158.31754 | M23: =D23 -> 158.47438 | N23: =E23 -> 158.29108 | O23: =F23 -> 158.44307 | P23: =G23 -> 159.43 | Q23: =H23 -> 158.46821 | R23: =I23 -> 157.997
C24: NaNMC | D24: NaMVP | E24: NaMMO | F24: NaNMMT | G24: NaPBA | H24: LiNMC | I24: LiFP | K24: per cell | L24: =C24 -> NaNMC | M24: =D24 -> NaMVP | N24: =E24 -> NaMMO | O24: =F24 -> NaNMMT | P24: =G24 -> NaPBA | Q24: =H24 -> LiNMC | R24: =I24 -> LiFP
A25: AP | B25: =B5 -> Acidification | C25: =H5 -> 0.15678 | D25: =R5 -> 0.13554 | E25: =AB5 -> 0.07892 | F25: =AL5 -> 0.08394 | G25: =AV5 -> 0.09139 | H25: =BF5 -> 0.07144 | I25: =BP5 -> 0.05301 | J25: =I5 -> molc H+ eq | K25: AP | L25: =C25 -> 0.15678 | M25: =D25 -> 0.13554 | N25: =E25 -> 0.07892 | O25: =F25 -> 0.08394 | P25: =G25 -> 0.09139 | Q25: =H25 -> 0.07144 | R25: =I25 -> 0.05301 | S25: =J25 -> molc H+ eq
A26: GWP | B26: =B6 -> Climate change | C26: =H6 -> 13.71866 | D26: =R6 -> 14.20745 | E26: =AB6 -> 8.28422 | F26: =AL6 -> 8.01709 | G26: =AV6 -> 13.87795 | H26: =BF6 -> 7.10008 | I26: =BP6 -> 7.83497 | J26: =I6 -> kg CO2 eq | K26: GWP | L26: =C26 -> 13.71866 | M26: =D26 -> 14.20745 | N26: =E26 -> 8.28422 | O26: =F26 -> 8.01709 | P26: =G26 -> 13.87795 | Q26: =H26 -> 7.10008 | R26: =I26 -> 7.83497 | S26: =J26 -> kg CO2 eq
A27: FWEcoTox | B27: =B7 -> Freshwater ecotoxicity | C27: =H7 -> 549.87634 | D27: =R7 -> 376.75458 | E27: =AB7 -> 123.10079 | F27: =AL7 -> 203.26992 | G27: =AV7 -> 208.92841 | H27: =BF7 -> 969.27582 | I27: =BP7 -> 1256.8352 | J27: =I7 -> CTUe | K27: Htox | L27: =(C29+C30)*1000 -> 0.01834956 | M27: =(D29+D30)*1000 -> 0.0276206 | N27: =(E29+E30)*1000 -> 0.002749595 | O27: =(F29+F30)*1000 -> 0.00466717 | P27: =(G29+G30)*1000 -> 0.0043253 | Q27: =(H29+H30)*1000 -> 0.01648859 | R27: =(I29+I30)*1000 -> 0.01577686 | S27: mCTUh
A28: FWEP | B28: =B8 -> Freshwater eutrophication | C28: =H8 -> 0.00493 | D28: =R8 -> 0.00581 | E28: =AB8 -> 0.00278 | F28: =AL8 -> 0.0026 | G28: =AV8 -> 0.00398 | H28: =BF8 -> 0.00541 | I28: =BP8 -> 0.01107 | J28: =I8 -> kg P eq | K28: RDP | L28: =C35 -> 0.00573 | M28: =D35 -> 0.00124 | N28: =E35 -> 0.00084 | O28: =F35 -> 0.00144 | P28: =G35 -> 0.00128 | Q28: =H35 -> 0.00503 | R28: =I35 -> 0.00486 | S28: =J35 -> kg Sb eq
A29: Htox,c | B29: =B9 -> Human toxicity, cancer effects | C29: =H9 -> 6.16316e-06 | D29: =R9 -> 1.50774e-05 | E29: =AB9 -> 9.65025e-07 | F29: =AL9 -> 1.62113e-06 | G29: =AV9 -> 1.6302e-06 | H29: =BF9 -> 3.32929e-06 | I29: =BP9 -> 1.92396e-06 | J29: =I9 -> CTUh | K29: ODP | L29: =C36 -> 1.8274e-06 | M29: =D36 -> 1.23342e-06 | N29: =E36 -> 7.39456e-07 | O29: =F36 -> 7.37173e-07 | P29: =G36 -> 1.41684e-06 | Q29: =H36 -> 7.8499e-07 | R29: =I36 -> 6.17554e-07 | S29: =J36 -> kg CFC-11 eq
A30: Htox,nc | B30: =B10 -> Human toxicity, non-cancer effects | C30: =H10 -> 1.21864e-05 | D30: =R10 -> 1.25432e-05 | E30: =AB10 -> 1.78457e-06 | F30: =AL10 -> 3.04604e-06 | G30: =AV10 -> 2.6951e-06 | H30: =BF10 -> 1.31593e-05 | I30: =BP10 -> 1.38529e-05 | J30: =I10 -> CTUh | K30: PMF | L30: =C37 -> 0.01158 | M30: =D37 -> 0.0106 | N30: =E37 -> 0.00658 | O30: =F37 -> 0.00562 | P30: =G37 -> 0.00758 | Q30: =H37 -> 0.00646 | R30: =I37 -> 0.00557 | S30: =J37 -> kg PM2.5 eq
A31: MEP | B31: =B11 -> Ionizing radiation E (interim) | C31: =H11 -> 2.5135e-05 | D31: =R11 -> 4.72612e-06 | E31: =AB11 -> 3.55227e-06 | F31: =AL11 -> 5.73509e-06 | G31: =AV11 -> 4.45032e-06 | H31: =BF11 -> 1.16005e-05 | I31: =BP11 -> 2.77624e-06 | J31: =I11 -> CTUe
A32: ADP | B32: =B12 -> Ionizing radiation HH | C32: =H12 -> 4.11443 | D32: =R12 -> 1.43068 | E32: =AB12 -> 1.17758 | F32: =AL12 -> 1.32416 | G32: =AV12 -> 1.4781 | H32: =BF12 -> 1.92503 | I32: =BP12 -> 0.86619 | J32: =I12 -> kBq U235 eq | K32: per kWh | L32: =L24 -> NaNMC | M32: =M24 -> NaMVP | N32: =N24 -> NaMMO | O32: =O24 -> NaNMMT | P32: =P24 -> NaPBA | Q32: =Q24 -> LiNMC | R32: =R24 -> LiFP
A33: ODP | B33: =B13 -> Land use | C33: =H13 -> 15.01635 | D33: =R13 -> 18.49076 | E33: =AB13 -> 9.26896 | F33: =AL13 -> 11.36192 | G33: =AV13 -> 12.28548 | H33: =BF13 -> 1.84147 | I33: =BP13 -> 1.90522 | J33: =I13 -> kg C deficit | K33: =K25 -> AP | L33: =L25/C$23*1000 -> 0.99028828 | M33: =M25/D$23*1000 -> 0.85528021 | N33: =N25/E$23*1000 -> 0.49857514 | O33: =O25/F$23*1000 -> 0.52978018 | P33: =P25/G$23*1000 -> 0.57322963 | Q33: =Q25/H$23*1000 -> 0.45081597 | R33: =R25/I$23*1000 -> 0.33551271 | S33: =S25 -> molc H+ eq
A34: PMF | B34: =B14 -> Marine eutrophication | C34: =H14 -> 0.02472 | D34: =R14 -> 0.02029 | E34: =AB14 -> 0.01545 | F34: =AL14 -> 0.01576 | G34: =AV14 -> 0.01908 | H34: =BF14 -> 0.0099 | I34: =BP14 -> 0.00984 | J34: =I14 -> kg N eq | K34: =K26 -> GWP | L34: =L26/C$23*1000 -> 86.652814 | M34: =M26/D$23*1000 -> 89.651401 | N34: =N26/E$23*1000 -> 52.335354 | O34: =O26/F$23*1000 -> 50.599182 | P34: =P26/G$23*1000 -> 87.047293 | Q34: =Q26/H$23*1000 -> 44.804444 | R34: =R26/I$23*1000 -> 49.589361 | S34: =S26 -> kg CO2 eq
A35: TEP | B35: =B15 -> Mineral, fossil & ren resource depletion | C35: =H15 -> 0.00573 | D35: =R15 -> 0.00124 | E35: =AB15 -> 0.00084 | F35: =AL15 -> 0.00144 | G35: =AV15 -> 0.00128 | H35: =BF15 -> 0.00503 | I35: =BP15 -> 0.00486 | J35: =I15 -> kg Sb eq | K35: =K27 -> Htox | L35: =L27/C$23*1000 -> 0.11590352 | M35: =M27/D$23*1000 -> 0.17429063 | N35: =N27/E$23*1000 -> 0.017370498 | O35: =O27/F$23*1000 -> 0.029456447 | P35: =P27/G$23*1000 -> 0.027129775 | Q35: =Q27/H$23*1000 -> 0.10404983 | R35: =R27/I$23*1000 -> 0.099855443 | S35: =S27 -> mCTUh
B36: =B16 -> Ozone depletion | C36: =H16 -> 1.8274e-06 | D36: =R16 -> 1.23342e-06 | E36: =AB16 -> 7.39456e-07 | F36: =AL16 -> 7.37173e-07 | G36: =AV16 -> 1.41684e-06 | H36: =BF16 -> 7.8499e-07 | I36: =BP16 -> 6.17554e-07 | J36: =I16 -> kg CFC-11 eq | K36: =K28 -> RDP | L36: =L28/C$23*1000 -> 0.036193085 | M36: =M28/D$23*1000 -> 0.0078246087 | N36: =N28/E$23*1000 -> 0.0053066792 | O36: =O28/F$23*1000 -> 0.0090884376 | P36: =P28/G$23*1000 -> 0.0080286019 | Q36: =Q28/H$23*1000 -> 0.031741382 | R36: =R28/I$23*1000 -> 0.030760079 | S36: =S28 -> kg Sb eq
B37: =B17 -> Particulate matter | C37: =H17 -> 0.01158 | D37: =R17 -> 0.0106 | E37: =AB17 -> 0.00658 | F37: =AL17 -> 0.00562 | G37: =AV17 -> 0.00758 | H37: =BF17 -> 0.00646 | I37: =BP17 -> 0.00557 | J37: =I17 -> kg PM2.5 eq | K37: =K29 -> ODP | L37: =L29/C$23*1000 -> 1.1542625e-05 | M37: =M29/D$23*1000 -> 7.7830878e-06 | N37: =N29/E$23*1000 -> 4.6714949e-06 | O37: =O29/F$23*1000 -> 4.6526047e-06 | P37: =P29/G$23*1000 -> 8.8869096e-06 | Q37: =Q29/H$23*1000 -> 4.9536118e-06 | R37: =R29/I$23*1000 -> 3.908644e-06 | S37: =S29 -> kg CFC-11 eq
B38: =B18 -> Photochemical ozone formation | C38: =H18 -> 0.05783 | D38: =R18 -> 0.05802 | E38: =AB18 -> 0.03632 | F38: =AL18 -> 0.03502 | G38: =AV18 -> 0.04534 | H38: =BF18 -> 0.02705 | I38: =BP18 -> 0.02767 | J38: =I18 -> kg NMVOC eq | K38: =K30 -> PMF | L38: =L30/C$23*1000 -> 0.07314414 | M38: =M30/D$23*1000 -> 0.066887784 | N38: =N30/E$23*1000 -> 0.041568987 | O38: =O30/F$23*1000 -> 0.035470152 | P38: =P30/G$23*1000 -> 0.047544377 | Q38: =Q30/H$23*1000 -> 0.040765274 | R38: =R30/I$23*1000 -> 0.035253835 | S38: =S30 -> kg PM2.5 eq
B39: =B19 -> Terrestrial eutrophication | C39: =H19 -> 0.22917 | D39: =R19 -> 0.20654 | E39: =AB19 -> 0.16694 | F39: =AL19 -> 0.154 | G39: =AV19 -> 0.19186 | H39: =BF19 -> 0.09109 | I39: =BP19 -> 0.10404 | J39: =I19 -> molc N eq
B40: =B20 -> Water resource depletion | C40: =H20 -> 15.68326 | D40: =R20 -> 6.97262 | E40: =AB20 -> 5.00015 | F40: =AL20 -> 5.58113 | G40: =AV20 -> 7.6298 | H40: =BF20 -> 8.01798 | I40: =BP20 -> 4.95109 | J40: =I20 -> m3 water eq
B41: GWP | E41: =E3 -> Na-Ion battery cell, prismatic, Na-NMC(111)-HC (2021) | L41: =B41 -> GWP | O41: =O3 -> Na-Ion battery cell, prismatic, NaMVP-HC (2021) | V41: =L41 -> GWP | Y41: =Y3 -> Na-Ion battery cell, prismatic, NaMMO-HC (2021) | AF41: =V41 -> GWP | AI41: =AI3 -> Na-Ion battery cell, prismatic, NaNMMT (2021) | AP41: =AF41 -> GWP | AS41: =AS3 -> Na-Ion battery cell, prismatic, NaPBA-HC (2021) | AZ41: =AP41 -> GWP | BC41: =BC3 -> Li-Ion battery cell, prismatic, NMC622-C (2021) | BJ41: =AP41 -> GWP | BM41: =BM3 -> Li-Ion battery cell, prismatic, LFP-C (2021)
...

Sheet Recycling
B1: HYDROMETALLURGICAL RECYCLING | L1: =B1 -> HYDROMETALLURGICAL RECYCLING | V1: =L1 -> HYDROMETALLURGICAL RECYCLING | AF1: =V1 -> HYDROMETALLURGICAL RECYCLING | AP1: =AF1 -> HYDROMETALLURGICAL RECYCLING | AZ1: =AP1 -> HYDROMETALLURGICAL RECYCLING | BJ1: =AZ1 -> HYDROMETALLURGICAL RECYCLING
B2: Na-Ion battery cell, prismatic, Na-NMC(111)-HC (2021) | L2: Na-Ion battery cell, prismatic, NMO-HC, aqueous electrolyte (2021) | V2: Recycling of Na-Ion battery cell, prismatic, NMO-HC (2021) | AF2: Na-Ion battery cell, prismatic, NMMT - NaNiMnMgTiO-HC (2021) | AP2: Li-Ion battery cell, prismatic, NMC111-C (2021) | AZ2: Li-Ion battery cell, prismatic, NMC622-C (2021) | BJ2: Li-Ion battery cell, prismatic, LFP-C (2021)
B4: Impact analysis | E4: =B2 -> Na-Ion battery cell, prismatic, Na-NMC(111)-HC (2021) | L4: =B4 -> Impact analysis | O4: =L2 -> Na-Ion battery cell, prismatic, NMO-HC, aqueous electrolyte (2021) | V4: =L4 -> Impact analysis | Y4: =V2 -> Recycling of Na-Ion battery cell, prismatic, NMO-HC (2021) | AF4: =V4 -> Impact analysis | AI4: =AF2 -> Na-Ion battery cell, prismatic, NMMT - NaNiMnMgTiO-HC (2021) | AP4: =AF4 -> Impact analysis | AS4: =AP2 -> Li-Ion battery cell, prismatic, NMC111-C (2021) | AZ4: =AP4 -> Impact analysis | BC4: =AZ2 -> Li-Ion battery cell, prismatic, NMC622-C (2021) | BJ4: =AP4 -> Impact analysis | BM4: =BJ2 -> Li-Ion battery cell, prismatic, LFP-C (2021)
AP5: Name | AQ5: Category | AR5: Inventory result | AS5: Unit | AT5: Impact factor | AU5: Unit | AV5: Impact result | AW5: Unit
AP6: Acidification | AV6: -0.10025 | AW6: molc H+ eq
AP7: Climate change | AV7: -6.90694 | AW7: kg CO2 eq
AP8: Freshwater ecotoxicity | AV8: -1505.3684 | AW8: CTUe
AP9: Freshwater eutrophication | AV9: -0.00717 | AW9: kg P eq
AP10: Human toxicity, cancer effects | AV10: -5.46639e-06 | AW10: CTUh
AP11: Human toxicity, non-cancer effects | AV11: -1.88736e-05 | AW11: CTUh
AP12: Ionizing radiation E (interim) | AV12: -1.97621e-05 | AW12: CTUe
AP13: Ionizing radiation HH | AV13: -2.76897 | AW13: kBq U235 eq
AP14: Land use | AV14: -5.57033 | AW14: kg C deficit
AP15: Marine eutrophication | AV15: -0.0151 | AW15: kg N eq
AP16: Mineral, fossil & ren resource depletion | AV16: -0.00792 | AW16: kg Sb eq
AP17: Ozone depletion | AV17: -6.90727e-07 | AW17: kg CFC-11 eq
... AP21: Water resource depletion | AV21: -11.64072 | AW21: m3 water eq
B40: Contribution tree | E40: =E4 -> Na-Ion battery cell, prismatic, Na-NMC(111)-HC (2021) | L40: =B40 -> Contribution tree | O40: =O4 -> Na-Ion battery cell, prismatic, NMO-HC, aqueous electrolyte (2021) | V40: =L40 -> Contribution tree | Y40: =Y4 -> Recycling of Na-Ion battery cell, prismatic, NMO-HC (2021) | AF40: =V40 -> Contribution tree | AI40: =AI4 -> Na-Ion battery cell, prismatic, NMMT - NaNiMnMgTiO-HC (2021) | AP40: =AF40 -> Contribution tree | AS40: =AS4 -> Li-Ion battery cell, prismatic, NMC111-C (2021) | AZ40: =AP40 -> Contribution tree | BC40: =BC4 -> Li-Ion battery cell, prismatic, NMC622-C (2021) | BJ40: =AP40 -> Contribution tree | BM40: =BM4 -> Li-Ion battery cell, prismatic, LFP-C (2021)
B41: GWP | L41: =B41 -> GWP | V41: =L41 -> GWP | AF41: =V41 -> GWP | AP41: =AF41 -> GWP | AZ41: =AP41 -> GWP | BJ41: =AP41 -> GWP
AP42: Contribution | AS42: Process | AT42: Amount | AU42: Unit
AQ43: 1 | AS43: Treatment of Li-Ion battery cell, NMC111-C prismatic, hydrometallurgical treatment - RER | AT43: -6.90694 | AU43: kg CO2 eq
AR44: -0.0264 | AS44: market for lime, hydrated, packed | lime, hydrated, packed | Cutoff, U - RER | AT44: 0.18226 | AU44: kg CO2 eq
AR45: -0.0144 | AS45: market for sulfuric acid | sulfuric acid | Cutoff, U - RoW | AT45: 0.09925 | AU45: kg CO2 eq
AR46: -0.0095 | AS46: market group for waste plastic, mixture | waste plastic, mixture | Cutoff, U - Europe without Switzerland | AT46: 0.06577 | AU46: kg CO2 eq
AR47: -0.0087 | AS47: market group for electricity, medium voltage | electricity, medium voltage | Cutoff, U - Europe without Switzerland | AT47: 0.06034 | AU47: kg CO2 eq
AR48: -0.0078 | AS48: market for chemical factory, organics | chemical factory, organics | Cutoff, U - GLO | AT48: 0.0536 | AU48: kg CO2 eq
AR49: -0.0069 | AS49: market for chemicals, inorganic | chemical, inorganic | Cutoff, U - GLO | AT49: 0.04764 | AU49: kg CO2 eq
AR50: -0.0002 | AS50: market for inert waste, for final disposal | inert waste, for final disposal | Cutoff, U - RoW | AT50: 0.00167 | AU50: kg CO2 eq
AR51: 0 | AS51: market for wastewater, average | wastewater, average | Cutoff, U - Europe without Switzerland | AT51: 0.00023 | AU51: kg CO2 eq
AR52: 0.0005 | AS52: treatment of waste gypsum, sanitary landfill | waste gypsum | Cutoff, U - Europe without Switzerland | AT52: -0.00314 | AU52: kg CO2 eq
AR53: 0.0207 | AS53: market for manganese sulfate | manganese sulfate | Cutoff, U - GLO | AT53: -0.14314 | AU53: kg CO2 eq
AR54: 0.0704 | AS54: market for aluminium, wrought alloy | aluminium, wrought alloy | Cutoff, U - GLO | AT54: -0.48591 | AU54: kg CO2 eq
AR55: 0.0903 | AS55: market for copper, cathode | copper, cathode | Cutoff, U - GLO | AT55: -0.62378 | AU55: kg CO2 eq
... AR58: 0.5207 | AS58: market for cobalt carbonate | cobalt carbonate | Cutoff, U - GLO | AT58: -3.59622 | AU58: kg CO2 eq
AP62: RDP
AP63: Contribution | AS63: Process | AT63: Amount | AU63: Unit
AQ64: 1 | AS64: Treatment of Li-Ion battery cell, NMC111-C prismatic, hydrometallurgical treatment - RER | AT64: -0.00792 | AU64: kg Sb eq
AR65: -0.0085 | AS65: market for sulfuric acid | sulfuric acid | Cutoff, U - RoW | AT65: 6.72104e-05 | AU65: kg Sb eq
AR66: -0.0028 | AS66: market for chemical factory, organics | chemical factory, organics | Cutoff, U - GLO | AT66: 2.24188e-05 | AU66: kg Sb eq
AR67: -0.0019 | AS67: market for chemicals, inorganic | chemical, inorganic | Cutoff, U - GLO | AT67: 1.53827e-05 | AU67: kg Sb eq
...

Sheet Resume_SensAnal
B3: Results summary
D6: =Recycling!AJ142 -> NaNMC | G6: =Recycling!AM142 -> NaMVP | J6: =Recycling!AP142 -> NaMMO | M6: =Recycling!AS142 -> NaNMMT | P6: =Recycling!AV142 -> NaPBA | S6: =Recycling!AY142 -> LiNMC | V6: =Recycling!BB142 -> LiFP
C7: =Recycling!AI143 -> per cell | D7: =Recycling!AJ143 -> Prod | E7: =Recycling!AK143 -> Rec | F7: =Recycling!AL143 -> Net | G7: =Recycling!AM143 -> Prod | H7: =Recycling!AN143 -> Rec | I7: =Recycling!AO143 -> Net | J7: =Recycling!AP143 -> Prod | ... X7: =Recycling!BD143 -> Net
C8: =Recycling!AI144 -> AP | D8: =Recycling!AJ144 -> 0.15678 | E8: =Recycling!AK144 -> -0.09782 | F8: =Recycling!AL144 -> 0.05896 | G8: =Recycling!AM144 -> 0.13554 | H8: =Recycling!AN144 -> -0.03407 | I8: =Recycling!AO144 -> 0.10147 | J8: =Recycling!AP144 -> 0.07892 | ... Y8: =Recycling!BE144 -> molc H+ eq
C9: =Recycling!AI145 -> GWP | D9: =Recycling!AJ145 -> 13.71866 | E9: =Recycling!AK145 -> -5.05023 | F9: =Recycling!AL145 -> 8.66843 | G9: =Recycling!AM145 -> 14.20745 | H9: =Recycling!AN145 -> -1.31878 | I9: =Recycling!AO145 -> 12.88867 | J9: =Recycling!AP145 -> 8.28422 | ... Y9: =Recycling!BE145 -> kg CO2 eq
C10: =Recycling!AI146 -> Htox | D10: =Recycling!AJ146 -> 0.01834956 | E10: =Recycling!AK146 -> -0.01257218 | F10: =Recycling!AL146 -> 0.00577738 | G10: =Recycling!AM146 -> 0.0276206 | H10: =Recycling!AN146 -> -0.00067376 | I10: =Recycling!AO146 -> 0.02694684 | J10: =Recycling!AP146 -> 0.002749595 | ... Y10: =Recycling!BE146 -> mCTUh
C11: =Recycling!AI147 -> RDP | D11: =Recycling!AJ147 -> 0.00573 | E11: =Recycling!AK147 -> -0.00447 | F11: =Recycling!AL147 -> 0.00126 | G11: =Recycling!AM147 -> 0.00124 | H11: =Recycling!AN147 -> -0.00062 | I11: =Recycling!AO147 -> 0.00062 | J11: =Recycling!AP147 -> 0.00084 | ... Y11: =Recycling!BE147 -> kg Sb eq
C12: =Recycling!AI148 -> ODP | D12: =Recycling!AJ148 -> 1.8274e-06 | E12: =Recycling!AK148 -> -6.35962e-07 | F12: =Recycling!AL148 -> 1.191438e-06 | G12: =Recycling!AM148 -> 1.23342e-06 | H12: =Recycling!AN148 -> -1.03138e-07 | I12: =Recycling!AO148 -> 1.130282e-06 | J12: =Recycling!AP148 -> 7.39456e-07 | ... Y12: =Recycling!BE148 -> kg CFC-11 eq
C13: =Recycling!AI149 -> PMF | D13: =Recycling!AJ149 -> 0.01158 | E13: =Recycling!AK149 -> -0.00689 | F13: =Recycling!AL149 -> 0.00469 | G13: =Recycling!AM149 -> 0.0106 | H13: =Recycling!AN149 -> -0.00238 | I13: =Recycling!AO149 -> 0.00822 | J13: =Recycling!AP149 -> 0.00658 | ... Y13: =Recycling!BE149 -> kg PM2.5 eq
D14: =Recycling!AJ150 -> NaNMC | G14: =Recycling!AM150 -> NaMVP | J14: =Recycling!AP150 -> NaMMO | M14: =Recycling!AS150 -> NaNMMT | P14: =Recycling!AV150 -> NaPBA | S14: =Recycling!AY150 -> LiNMC | V14: =Recycling!BB150 -> LiFP
C15: =Recycling!AI151 -> per kWh | D15: =Recycling!AJ151 -> Prod | E15: =Recycling!AK151 -> Rec | F15: =Recycling!AL151 -> Net | G15: =Recycling!AM151 -> Prod | H15: =Recycling!AN151 -> Rec | I15: =Recycling!AO151 -> Net | J15: =Recycling!AP151 -> Prod | ... X15: =Recycling!BD151 -> Net
C16: =Recycling!AI152 -> AP | D16: =Recycling!AJ152 -> 0.99028828 | E16: =Recycling!AK152 -> -0.61787217 | F16: =Recycling!AL152 -> 0.37241611 | G16: =Recycling!AM152 -> 0.85528021 | H16: =Recycling!AN152 -> -0.21498743 | I16: =Recycling!AO152 -> 0.64029278 | J16: =Recycling!AP152 -> 0.49857514 | ... X16: =Recycling!BD152 -> 0.21918138 | Y16: =Y8 -> molc H+ eq
C17: =Recycling!AI153 -> GWP | D17: =Recycling!AJ153 -> 86.652814 | E17: =Recycling!AK153 -> -31.899372 | F17: =Recycling!AL153 -> 54.753442 | G17: =Recycling!AM153 -> 89.651401 | H17: =Recycling!AN153 -> -8.3217238 | I17: =Recycling!AO153 -> 81.329677 | J17: =Recycling!AP153 -> 52.335354 | ... X17: =Recycling!BD153 -> 43.045629 | Y17: =Y9 -> kg CO2 eq
C18: =Recycling!AI154 -> Htox | D18: =Recycling!AJ154 -> 0.11590352 | E18: =Recycling!AK154 -> -0.079411165 | F18: =Recycling!AL154 -> 0.036492357 | G18: =Recycling!AM154 -> 0.17429063 | H18: =Recycling!AN154 -> -0.004251539 | I18: =Recycling!AO154 -> 0.1700391 | J18: =Recycling!AP154 -> 0.017370498 | ... X18: =Recycling!BD154 -> 0.026197194 | Y18: =Y10 -> mCTUh
C19: =Recycling!AI155 -> RDP | D19: =Recycling!AJ155 -> 0.036193085 | E19: =Recycling!AK155 -> -0.028234396 | F19: =Recycling!AL155 -> 0.0079586888 | G19: =Recycling!AM155 -> 0.0078246087 | H19: =Recycling!AN155 -> -0.0039123043 | I19: =Recycling!AO155 -> 0.0039123043 | J19: =Recycling!AP155 -> 0.0053066792 | ... X19: =Recycling!BD155 -> 0.0058228955 | Y19: =Y11 -> kg Sb eq
C20: =Recycling!AI156 -> ODP | D20: =Recycling!AJ156 -> 1.1542625e-05 | E20: =Recycling!AK156 -> -4.0170029e-06 | F20: =Recycling!AL156 -> 7.5256225e-06 | G20: =Recycling!AM156 -> 7.7830878e-06 | H20: =Recycling!AN156 -> -6.5081814e-07 | I20: =Recycling!AO156 -> 7.1322697e-06 | J20: =Recycling!AP156 -> 4.6714949e-06 | ... X20: =Recycling!BD156 -> 3.6196093e-06 | Y20: =Y12 -> kg CFC-11 eq
C21: =Recycling!AI157 -> PMF | D21: =Recycling!AJ157 -> 0.07314414 | E21: =Recycling!AK157 -> -0.043520132 | F21: =Recycling!AL157 -> 0.029624008 | G21: =Recycling!AM157 -> 0.066887784 | H21: =Recycling!AN157 -> -0.015018201 | I21: =Recycling!AO157 -> 0.051869583 | J21: =Recycling!AP157 -> 0.041568987 | ... X21: =Recycling!BD157 -> 0.019747211 | Y21: =Y13 -> kg PM2.5 eq
D23: =($S17-D17)/$S17 -> -0.93402277 | G23: =($S17-G17)/$S17 -> -1.0009489 | J23: =($S17-J17)/$S17 -> -0.16808401 | M23: =($S17-M17)/$S17 -> -0.12933401 | P23: =($S17-P17)/$S17 -> -0.94282723 | S23: =($S17-S17)/$S17 -> 0 | V23: =($S17-V17)/$S17 -> -0.10679559
B26: Sensitivity Analysis
A28: ENERGY DENSITY | D28: Energy density | E28: =Production!C22 -> 136.31 | F28: =Production!D22 -> 152.46717 | G28: =Production!E22 -> 157.08 | H28: =Production!F22 -> 171.91013 | I28: =Production!G22 -> 124.1 | J28: =Production!H22 -> 272.11478 | K28: =Production!I22 -> 197.41872 | L28: Wh/kg
B29: GWP | D29: Production - GWP | M29: Net - GWP | Z29: HTP
D30: Energy density - absolute values | E30: =Production!C24 -> NaNMC | F30: =Production!D24 -> NaMVP | G30: =Production!E24 -> NaMMO | H30: =Production!F24 -> NaNMMT | I30: =Production!G24 -> NaPBA | J30: =Production!H24 -> LiNMC | K30: =Production!I24 -> LiFP | M30: =D30 -> Energy density - absolute values | N30: =E30 -> NaNMC | O30: =F30 -> NaMVP | P30: =G30 -> NaMMO | Q30: =H30 -> NaNMMT | R30: =I30 -> NaPBA | S30: =J30 -> LiNMC | T30: =K30 -> LiFP | AB30: Energy density - absolute values | AC30: =N30 -> NaNMC | AD30: =O30 -> NaMVP | AE30: =P30 -> NaMMO | AF30: =Q30 -> NaNMMT | AG30: =R30 -> NaPBA | AH30: =S30 -> LiNMC | AI30: =T30 -> LiFP | AL30: =AC30 -> NaNMC | AM30: =AD30 -> NaMVP | AN30: =AE30 -> NaMMO | AO30: =AF30 -> NaNMMT | AP30: =AG30 -> NaPBA | AQ30: =AH30 -> LiNMC | AR30: =AI30 -> LiFP
D31: 100 | E31: =D$17*E$28/$D31 -> 118.11645 | F31: =G$17*F$28/$D31 -> 136.68896 | G31: =J$17*G$28/$D31 -> 82.208375 | H31: =M$17*H$28/$D31 -> 86.985118 | I31: =P$17*I$28/$D31 -> 108.02569 | J31: =S$17*J$28/$D31 -> 121.91951 | K31: =V$17*K$28/$D31 -> 97.898683 | M31: =D31 -> 100 | N31: =F$17*E$28/$D31 -> 74.634417 | O31: =I$17*F$28/$D31 -> 124.00106 | P31: =L$17*G$28/$D31 -> 72.250351 | Q31: =O$17*H$28/$D31 -> 64.053507 | R31: =R$17*I$28/$D31 -> 91.756549 | S31: =U$17*J$28/$D31 -> 74.6127 | T31: =X$17*K$28/$D31 -> 84.980131 | AB31: 50 | AC31: =D$18*E$28/$D31 -> 0.15798809 | AD31: =G$18*F$28/$D31 -> 0.265736 | AE31: =J$18*G$28/$D31 -> 0.027285579 | AF31: =M$18*H$28/$D31 -> 0.050638615 | AG31: =P$18*I$28/$D31 -> 0.033668051 | AH31: =S$18*J$28/$D31 -> 0.28313496 | AI31: =V$18*K$28/$D31 -> 0.19713334 | AL31: =F$18*E$28/$D31 -> 0.049742732 | AM31: =I$18*F$28/$D31 -> 0.2592538 | AN31: =L$18*G$28/$D31 -> 0.022605452 | AO31: =O$18*H$28/$D31 -> 0.024496457 | AP31: =R$18*I$28/$D31 -> 0.024034721 | AQ31: =U$18*J$28/$D31 -> 0.051919098 | AR31: =X$18*K$28/$D31 -> 0.051718167
D32: 110 | E32: =D$17*E$28/$D32 -> 107.37859 | F32: =G$17*F$28/$D32 -> 124.26269 | G32: =J$17*G$28/$D32 -> 74.734886 | H32: =M$17*H$28/$D32 -> 79.07738 | I32: =P$17*I$28/$D32 -> 98.205174 | J32: =S$17*J$28/$D32 -> 110.83592 | K32: =V$17*K$28/$D32 -> 88.998803 | M32: =D32 -> 110 | N32: =F$17*E$28/$D32 -> 67.84947 | O32: =I$17*F$28/$D32 -> 112.72824 | P32: =L$17*G$28/$D32 -> 65.682137 | Q32: =O$17*H$28/$D32 -> 58.230461 | R32: =R$17*I$28/$D32 -> 83.415045 | S32: =U$17*J$28/$D32 -> 67.829728 | T32: =X$17*K$28/$D32 -> 77.254665 | AB32: 60 | AC32: =D$18*E$28/$D32 -> 0.14362554 | AD32: =G$18*F$28/$D32 -> 0.24157818 | AE32: =J$18*G$28/$D32 -> 0.024805071 | AF32: =M$18*H$28/$D32 -> 0.046035104 | AG32: =P$18*I$28/$D32 -> 0.030607319 | AH32: =S$18*J$28/$D32 -> 0.25739542 | AI32: =V$18*K$28/$D32 -> 0.17921213 | AL32: =F$18*E$28/$D32 -> 0.045220665 | AM32: =I$18*F$28/$D32 -> 0.23568527 | AN32: =L$18*G$28/$D32 -> 0.020550411 | AO32: =O$18*H$28/$D32 -> 0.022269507 | AP32: =R$18*I$28/$D32 -> 0.021849746 | AQ32: =U$18*J$28/$D32 -> 0.04719918 | AR32: =X$18*K$28/$D32 -> 0.047016515
D33: 120 | E33: =D$17*E$28/$D33 -> 98.430376 | F33: =G$17*F$28/$D33 -> 113.90746 | G33: =J$17*G$28/$D33 -> 68.506979 | H33: =M$17*H$28/$D33 -> 72.487598 | I33: =P$17*I$28/$D33 -> 90.021409 | J33: =S$17*J$28/$D33 -> 101.5996 | K33: =V$17*K$28/$D33 -> 81.582236 | M33: =D33 -> 120 | N33: =F$17*E$28/$D33 -> 62.195347 | O33: =I$17*F$28/$D33 -> 103.33422 | P33: =L$17*G$28/$D33 -> 60.208626 | Q33: =O$17*H$28/$D33 -> 53.377923 | R33: =R$17*I$28/$D33 -> 76.463791 | S33: =U$17*J$28/$D33 -> 62.17725 | T33: =X$17*K$28/$D33 -> 70.816776 | AB33: 70 | AC33: =D$18*E$28/$D33 -> 0.13165674 | AD33: =G$18*F$28/$D33 -> 0.22144667 | AE33: =J$18*G$28/$D33 -> 0.022737982 | AF33: =M$18*H$28/$D33 -> 0.042198846 | AG33: =P$18*I$28/$D33 -> 0.028056709 | AH33: =S$18*J$28/$D33 -> 0.2359458 | AI33: =V$18*K$28/$D33 -> 0.16427778 | AL33: =F$18*E$28/$D33 -> 0.041452276 | AM33: =I$18*F$28/$D33 -> 0.21604483 | AN33: =L$18*G$28/$D33 -> 0.018837877 | AO33: =O$18*H$28/$D33 -> 0.020413714 | AP33: =R$18*I$28/$D33 -> 0.020028934 | AQ33: =U$18*J$28/$D33 -> 0.043265915 | AR33: =X$18*K$28/$D33 -> 0.043098472
D34: 130 | E34: =D$17*E$28/$D34 -> 90.858809 | F34: =G$17*F$28/$D34 -> 105.14535 | G34: =J$17*G$28/$D34 -> 63.237211 | H34: =M$17*H$28/$D34 -> 66.911629 | I34: =P$17*I$28/$D34 -> 83.096686 | J34: =S$17*J$28/$D34 -> 93.784242 | K34: =V$17*K$28/$D34 -> 75.306679 | M34: =D34 -> 130 | N34: =F$17*E$28/$D34 -> 57.41109 | O34: =I$17*F$28/$D34 -> 95.38543 | P34: =L$17*G$28/$D34 -> 55.577193 | Q34: =O$17*H$28/$D34 -> 49.271929 | R34: =R$17*I$28/$D34 -> 70.581961 | S34: =U$17*J$28/$D34 -> 57.394385 | T34: =X$17*K$28/$D34 -> 65.369332 | AB34: 80 | AC34: =D$18*E$28/$D34 -> 0.1215293 | AD34: =G$18*F$28/$D34 -> 0.20441231 | AE34: =J$18*G$28/$D34 -> 0.020988907 | AF34: =M$18*H$28/$D34 -> 0.038952781 | AG34: =P$18*I$28/$D34 -> 0.0258985 | AH34: =S$18*J$28/$D34 -> 0.21779613 | AI34: =V$18*K$28/$D34 -> 0.15164103 | AL34: =F$18*E$28/$D34 -> 0.03826364 | AM34: =I$18*F$28/$D34 -> 0.199426 | AN34: =L$18*G$28/$D34 -> 0.017388809 | AO34: =O$18*H$28/$D34 -> 0.018843429 | AP34: =R$18*I$28/$D34 -> 0.018488247 | AQ34: =U$18*J$28/$D34 -> 0.039937768 | AR34: =X$18*K$28/$D34 -> 0.039783205
D35: 140 | E35: =D$17*E$28/$D35 -> 84.368894 | F35: =G$17*F$28/$D35 -> 97.634968 | G35: =J$17*G$28/$D35 -> 58.720268 | H35: =M$17*H$28/$D35 -> 62.132227 | I35: =P$17*I$28/$D35 -> 77.161208 | J35: =S$17*J$28/$D35 -> 87.085368 | K35: =V$17*K$28/$D35 -> 69.927631 | M35: =D35 -> 140 | N35: =F$17*E$28/$D35 -> 53.310298 | O35: =I$17*F$28/$D35 -> 88.572185 | P35: =L$17*G$28/$D35 -> 51.607394 | Q35: =O$17*H$28/$D35 -> 45.752505 | R35: =R$17*I$28/$D35 -> 65.540392 | S35: =U$17*J$28/$D35 -> 53.294786 | T35: =X$17*K$28/$D35 -> 60.700094 | AB35: 90 | AC35: =D$18*E$28/$D35 -> 0.11284864 | AD35: =G$18*F$28/$D35 -> 0.18981143 | AE35: =J$18*G$28/$D35 -> 0.019489699 | AF35: =M$18*H$28/$D35 -> 0.036170439 | AG35: =P$18*I$28/$D35 -> 0.024048608 | AH35: =S$18*J$28/$D35 -> 0.20223926 | AI35: =V$18*K$28/$D35 -> 0.14080953 | AL35: =F$18*E$28/$D35 -> 0.035530523 | AM35: =I$18*F$28/$D35 -> 0.18518129 | AN35: =L$18*G$28/$D35 -> 0.016146752 | AO35: =O$18*H$28/$D35 -> 0.017497469 | AP35: =R$18*I$28/$D35 -> 0.017167658 | AQ35: =U$18*J$28/$D35 -> 0.03708507 | AR35: =X$18*K$28/$D35 -> 0.036941548
D36: 150 | E36: =D$17*E$28/$D36 -> 78.744301 | F36: =G$17*F$28/$D36 -> 91.12597 | G36: =J$17*G$28/$D36 -> 54.805583 | H36: =M$17*H$28/$D36 -> 57.990079 | I36: =P$17*I$28/$D36 -> 72.017127 | J36: =S$17*J$28/$D36 -> 81.279677 | K36: =V$17*K$28/$D36 -> 65.265789 | M36: =D36 -> 150 | N36: =F$17*E$28/$D36 -> 49.756278 | O36: =I$17*F$28/$D36 -> 82.667372 | P36: =L$17*G$28/$D36 -> 48.166901 | Q36: =O$17*H$28/$D36 -> 42.702338 | R36: =R$17*I$28/$D36 -> 61.171033 | S36: =U$17*J$28/$D36 -> 49.7418 | T36: =X$17*K$28/$D36 -> 56.653421 | AB36: 100 | AC36: =D$18*E$28/$D36 -> 0.10532539 | AD36: =G$18*F$28/$D36 -> 0.17715733 | AE36: =J$18*G$28/$D36 -> 0.018190386 | AF36: =M$18*H$28/$D36 -> 0.033759077 | AG36: =P$18*I$28/$D36 -> 0.022445367 | AH36: =S$18*J$28/$D36 -> 0.18875664 | AI36: =V$18*K$28/$D36 -> 0.13142223 | AL36: =F$18*E$28/$D36 -> 0.033161821 | AM36: =I$18*F$28/$D36 -> 0.17283587 | AN36: =L$18*G$28/$D36 -> 0.015070302 | AO36: =O$18*H$28/$D36 -> 0.016330971 | AP36: =R$18*I$28/$D36 -> 0.016023147 | AQ36: =U$18*J$28/$D36 -> 0.034612732 | AR36: =X$18*K$28/$D36 -> 0.034478778
D37: 160 | E37: =D$17*E$28/$D37 -> 73.822782 | F37: =G$17*F$28/$D37 -> 85.430597 | G37: =J$17*G$28/$D37 -> 51.380234 | H37: =M$17*H$28/$D37 -> 54.365699 | I37: =P$17*I$28/$D37 -> 67.516057 | J37: =S$17*J$28/$D37 -> 76.199697 | K37: =V$17*K$28/$D37 -> 61.186677 | M37: =D37 -> 160 | N37: =F$17*E$28/$D37 -> 46.64651 | O37: =I$17*F$28/$D37 -> 77.500662 | P37: =L$17*G$28/$D37 -> 45.156469 | Q37: =O$17*H$28/$D37 -> 40.033442 | R37: =R$17*I$28/$D37 -> 57.347843 | S37: =U$17*J$28/$D37 -> 46.632938 | T37: =X$17*K$28/$D37 -> 53.112582 | AB37: 110 | AC37: =D$18*E$28/$D37 -> 0.098742557 | AD37: =G$18*F$28/$D37 -> 0.166085 | AE37: =J$18*G$28/$D37 -> 0.017053487 | AF37: =M$18*H$28/$D37 -> 0.031649134 | AG37: =P$18*I$28/$D37 -> 0.021042532 | AH37: =S$18*J$28/$D37 -> 0.17695935 | AI37: =V$18*K$28/$D37 -> 0.12320834 | AL37: =F$18*E$28/$D37 -> 0.031089207 | AM37: =I$18*F$28/$D37 -> 0.16203363 | AN37: =L$18*G$28/$D37 -> 0.014128408 | AO37: =O$18*H$28/$D37 -> 0.015310286 | AP37: =R$18*I$28/$D37 -> 0.015021701 | AQ37: =U$18*J$28/$D37 -> 0.032449436 | AR37: =X$18*K$28/$D37 -> 0.032323854
D38: 170 | E38: =D$17*E$28/$D38 -> 69.480265 | F38: =G$17*F$28/$D38 -> 80.405268 | G38: =J$17*G$28/$D38 -> 48.357868 | H38: =M$17*H$28/$D38 -> 51.167716 | I38: =P$17*I$28/$D38 -> 63.544524 | J38: =S$17*J$28/$D38 -> 71.717362 | K38: =V$17*K$28/$D38 -> 57.587461 | M38: =D38 -> 170 | N38: =F$17*E$28/$D38 -> 43.902598 | O38: =I$17*F$28/$D38 -> 72.941799 | P38: =L$17*G$28/$D38 -> 42.500206 | Q38: =O$17*H$28/$D38 -> 37.678534 | R38: =R$17*I$28/$D38 -> 53.974441 | S38: =U$17*J$28/$D38 -> 43.889824 | T38: =X$17*K$28/$D38 -> 49.988312 | AB38: 120 | AC38: =D$18*E$28/$D38 -> 0.092934171 | AD38: =G$18*F$28/$D38 -> 0.1563153 | AE38: =J$18*G$28/$D38 -> 0.01605034 | AF38: =M$18*H$28/$D38 -> 0.02978742 | AG38: =P$18*I$28/$D38 -> 0.019804736 | AH38: =S$18*J$28/$D38 -> 0.16654998 | AI38: =V$18*K$28/$D38 -> 0.11596079 | AL38: =F$18*E$28/$D38 -> 0.02926043 | AM38: =I$18*F$28/$D38 -> 0.15250224 | AN38: =L$18*G$28/$D38 -> 0.013297325 | AO38: =O$18*H$28/$D38 -> 0.014409681 | AP38: =R$18*I$28/$D38 -> 0.014138071 | AQ38: =U$18*J$28/$D38 -> 0.030540646 | AR38: =X$18*K$28/$D38 -> 0.030422451
D39: 180 | E39: =D$17*E$28/$D39 -> 65.620251 | F39: =G$17*F$28/$D39 -> 75.938309 | G39: =J$17*G$28/$D39 -> 45.671319 | H39: =M$17*H$28/$D39 -> 48.325065 | I39: =P$17*I$28/$D39 -> 60.014273 | J39: =S$17*J$28/$D39 -> 67.733064 | K39: =V$17*K$28/$D39 -> 54.388157 | M39: =D39 -> 180 | N39: =F$17*E$28/$D39 -> 41.463565 | O39: =I$17*F$28/$D39 -> 68.889477 | P39: =L$17*G$28/$D39 -> 40.139084 | Q39: =O$17*H$28/$D39 -> 35.585282 | R39: =R$17*I$28/$D39 -> 50.975861 | S39: =U$17*J$28/$D39 -> 41.4515 | T39: =X$17*K$28/$D39 -> 47.211184 | AB39: 130 | AC39: =D$18*E$28/$D39 -> 0.087771162 | AD39: =G$18*F$28/$D39 -> 0.14763111 | AE39: =J$18*G$28/$D39 -> 0.015158655 | AF39: =M$18*H$28/$D39 -> 0.028132564 | AG39: =P$18*I$28/$D39 -> 0.018704473 | AH39: =S$18*J$28/$D39 -> 0.1572972 | AI39: =V$18*K$28/$D39 -> 0.10951852 | AL39: =F$18*E$28/$D39 -> 0.027634851 | AM39: =I$18*F$28/$D39 -> 0.14402989 | AN39: =L$18*G$28/$D39 -> 0.012558585 | AO39: =O$18*H$28/$D39 -> 0.013609143 | AP39: =R$18*I$28/$D39 -> 0.013352623 | AQ39: =U$18*J$28/$D39 -> 0.028843943 | AR39: =X$18*K$28/$D39 -> 0.028732315
D40: 190 | E40: =D$17*E$28/$D40 -> 62.166553 | F40: =G$17*F$28/$D40 -> 71.941556 | G40: =J$17*G$28/$D40 -> 43.267566 | H40: =M$17*H$28/$D40 -> 45.781641 | I40: =P$17*I$28/$D40 -> 56.855627 | J40: =S$17*J$28/$D40 -> 64.168166 | K40: =V$17*K$28/$D40 -> 51.525623 | M40: =D40 -> 190 | N40: =F$17*E$28/$D40 -> 39.281272 | O40: =I$17*F$28/$D40 -> 65.263715 | P40: =L$17*G$28/$D40 -> 38.026501 | Q40: =O$17*H$28/$D40 -> 33.712372 | R40: =R$17*I$28/$D40 -> 48.292921 | S40: =U$17*J$28/$D40 -> 39.269842 | T40: =X$17*K$28/$D40 -> 44.726385 | AB40: 140 | AC40: =D$18*E$28/$D40 -> 0.083151627 | AD40: =G$18*F$28/$D40 -> 0.13986105 | AE40: =J$18*G$28/$D40 -> 0.014360831 | AF40: =M$18*H$28/$D40 -> 0.026651903 | AG40: =P$18*I$28/$D40 -> 0.017720027 | AH40: =S$18*J$28/$D40 -> 0.1490184 | AI40: =V$18*K$28/$D40 -> 0.10375439 | AL40: =F$18*E$28/$D40 -> 0.026180385 | AM40: =I$18*F$28/$D40 -> 0.13644937 | AN40: =L$18*G$28/$D40 -> 0.011897606 | AO40: =O$18*H$28/$D40 -> 0.012892872 | AP40: =R$18*I$28/$D40 -> 0.012649853 | AQ40: =U$18*J$28/$D40 -> 0.027325841 | AR40: =X$18*K$28/$D40 -> 0.027220088
D41: 200 | E41: =D$17*E$28/$D41 -> 59.058226 | F41: =G$17*F$28/$D41 -> 68.344478 | G41: =J$17*G$28/$D41 -> 41.104187 | H41: =M$17*H$28/$D41 -> 43.492559 | I41: =P$17*I$28/$D41 -> 54.012846 | J41: =S$17*J$28/$D41 -> 60.959757 | K41: =V$17*K$28/$D41 -> 48.949342 | M41: =D41 -> 200 | N41: =F$17*E$28/$D41 -> 37.317208 | O41: =I$17*F$28/$D41 -> 62.000529 | P41: =L$17*G$28/$D41 -> 36.125176 | Q41: =O$17*H$28/$D41 -> 32.026754 | R41: =R$17*I$28/$D41 -> 45.878275 | S41: =U$17*J$28/$D41 -> 37.30635 | T41: =X$17*K$28/$D41 -> 42.490065 | AB41: 150 | AC41: =D$18*E$28/$D41 -> 0.078994046 | AD41: =G$18*F$28/$D41 -> 0.132868 | AE41: =J$18*G$28/$D41 -> 0.013642789 | AF41: =M$18*H$28/$D41 -> 0.025319307 | AG41: =P$18*I$28/$D41 -> 0.016834025 | AH41: =S$18*J$28/$D41 -> 0.14156748 | AI41: =V$18*K$28/$D41 -> 0.098566671 | AL41: =F$18*E$28/$D41 -> 0.024871366 | AM41: =I$18*F$28/$D41 -> 0.1296269 | AN41: =L$18*G$28/$D41 -> 0.011302726 | AO41: =O$18*H$28/$D41 -> 0.012248229 | AP41: =R$18*I$28/$D41 -> 0.01201736 | AQ41: =U$18*J$28/$D41 -> 0.025959549 | AR41: =X$18*K$28/$D41 -> 0.025859083
D42: 210 | E42: =D$17*E$28/$D42 -> 56.245929 | F42: =G$17*F$28/$D42 -> 65.089979 | G42: =J$17*G$28/$D42 -> 39.146845 | H42: =M$17*H$28/$D42 -> 41.421485 | I42: =P$17*I$28/$D42 -> 51.440805 | J42: =S$17*J$28/$D42 -> 58.056912 | K42: =V$17*K$28/$D42 -> 46.618421 | M42: =D42 -> 210 | N42: =F$17*E$28/$D42 -> 35.540198 | O42: =I$17*F$28/$D42 -> 59.048123 | P42: =L$17*G$28/$D42 -> 34.404929 | Q42: =O$17*H$28/$D42 -> 30.50167 | R42: =R$17*I$28/$D42 -> 43.693595 | S42: =U$17*J$28/$D42 -> 35.529857 | T42: =X$17*K$28/$D42 -> 40.466729 | AB42: 160 | AC42: =D$18*E$28/$D42 -> 0.075232424 | AD42: =G$18*F$28/$D42 -> 0.12654095 | AE42: =J$18*G$28/$D42 -> 0.012993133 | AF42: =M$18*H$28/$D42 -> 0.024113626 | AG42: =P$18*I$28/$D42 -> 0.016032405 | AH42: =S$18*J$28/$D42 -> 0.13482617 | AI42: =V$18*K$28/$D42 -> 0.09387302 | AL42: =F$18*E$28/$D42 -> 0.023687015 | AM42: =I$18*F$28/$D42 -> 0.12345419 | AN42: =L$18*G$28/$D42 -> 0.010764501 | AO42: =O$18*H$28/$D42 -> 0.01166498 | AP42: =R$18*I$28/$D42 -> 0.011445105 | AQ42: =U$18*J$28/$D42 -> 0.02472338 | AR42: =X$18*K$28/$D42 -> 0.024627699
... D51: 300 | E51: =D$17*E$28/$D51 -> 39.37215 | F51: =G$17*F$28/$D51 -> 45.562985 | G51: =J$17*G$28/$D51 -> 27.402792 | H51: =M$17*H$28/$D51 -> 28.995039 | I51: =P$17*I$28/$D51 -> 36.008564 | J51: =S$17*J$28/$D51 -> 40.639838 | K51: =V$17*K$28/$D51 -> 32.632894 | M51: =D51 -> 300 | N51: =F$17*E$28/$D51 -> 24.878139 | O51: =I$17*F$28/$D51 -> 41.333686 | P51: =L$17*G$28/$D51 -> 24.08345 | Q51: =O$17*H$28/$D51 -> 21.351169 | R51: =R$17*I$28/$D51 -> 30.585516 | S51: =U$17*J$28/$D51 -> 24.8709 | T51: =X$17*K$28/$D51 -> 28.32671 | AB51: 250 | AC51: =D$18*E$28/$D51 -> 0.052662697 | AD51: =G$18*F$28/$D51 -> 0.088578667 | AE51: =J$18*G$28/$D51 -> 0.0090951929 | AF51: =M$18*H$28/$D51 -> 0.016879538 | AG51: =P$18*I$28/$D51 -> 0.011222684 | AH51: =S$18*J$28/$D51 -> 0.094378321 | AI51: =V$18*K$28/$D51 -> 0.065711114 | AL51: =F$18*E$28/$D51 -> 0.016580911 | AM51: =I$18*F$28/$D51 -> 0.086417934 | AN51: =L$18*G$28/$D51 -> 0.0075351508 | AO51: =O$18*H$28/$D51 -> 0.0081654857 | AP51: =R$18*I$28/$D51 -> 0.0080115736 | AQ51: =U$18*J$28/$D51 -> 0.017306366 | AR51: =X$18*K$28/$D51 -> 0.017239389
D52: Wh/kg
C55: Energy density - relative values (relative to NMC)
D56: EngDens rel to NMC | M56: EngDens rel to NMC | AB56: EngDens rel to NMC | AK56: EngDens rel to NMC
D57: 0.9 | E57: =D$17/D57 -> 96.280905 | F57: =G$17/$D57 -> 99.612667 | G57: =J$17/$D57 -> 58.150394 | H57: =M$17/$D57 -> 56.221313 | I57: =P$17/$D57 -> 96.719215 | J57: =S$17/$D57 -> 49.782715 | K57: =V$17/$D57 -> 55.09929 | M57: 0.9 | N57: =F$17/M57 -> 60.837158 | O57: =I$17/$D57 -> 90.366308 | P57: =L$17/$D57 -> 51.106549 | Q57: =O$17/$D57 -> 41.399867 | R57: =R$17/$D57 -> 82.152878 | S57: =U$17/$D57 -> 30.466188 | T57: =X$17/$D57 -> 47.828476 | AB57: 0.9 | AC57: =D$18/AB57 -> 0.12878169 | AD57: =G$18/$D57 -> 0.19365626 | AE57: =J$18/$D57 -> 0.019300554 | AF57: =M$18/$D57 -> 0.032729385 | AG57: =P$18/$D57 -> 0.030144194 | AH57: =S$18/$D57 -> 0.11561092 | AI57: =V$18/$D57 -> 0.11095049 | AK57: 0.9 | AL57: =F$18/AK57 -> 0.040547063 | AM57: =I$18/$D57 -> 0.18893233 | AN57: =L$18/$D57 -> 0.015990049 | AO57: =O$18/$D57 -> 0.015832858 | AP57: =R$18/$D57 -> 0.021519134 | AQ57: =U$18/$D57 -> 0.021199836 | AR57: =X$18/$D57 -> 0.029107994
D58: 0.95 | E58: =D$17/D58 -> 91.213489 | F58: =G$17/$D58 -> 94.369895 | G58: =J$17/$D58 -> 55.089847 | H58: =M$17/$D58 -> 53.262297 | I58: =P$17/$D58 -> 91.62873 | J58: =S$17/$D58 -> 47.162572 | K58: =V$17/$D58 -> 52.199327 | M58: 0.95 | N58: =F$17/M58 -> 57.635202 | O58: =I$17/$D58 -> 85.610186 | P58: =L$17/$D58 -> 48.416731 | Q58: =O$17/$D58 -> 39.220927 | R58: =R$17/$D58 -> 77.829042 | S58: =U$17/$D58 -> 28.862704 | T58: =X$17/$D58 -> 45.311188 | AB58: 0.95 | AC58: =D$18/AB58 -> 0.12200371 | AD58: =G$18/$D58 -> 0.18346383 | AE58: =J$18/$D58 -> 0.018284735 | AF58: =M$18/$D58 -> 0.031006786 | AG58: =P$18/$D58 -> 0.028557658 | AH58: =S$18/$D58 -> 0.10952613 | AI58: =V$18/$D58 -> 0.10511099 | AK58: 0.95 | AL58: =F$18/AK58 -> 0.038413007 | AM58: =I$18/$D58 -> 0.17898852 | AN58: =L$18/$D58 -> 0.015148468 | AO58: =O$18/$D58 -> 0.014999549 | AP58: =R$18/$D58 -> 0.020386548 | AQ58: =U$18/$D58 -> 0.020084055 | AR58: =X$18/$D58 -> 0.027575994
...

Sheet Use Phase_Grid
D1: Changeable | E1: data needed
B3: Case | C3: 1 | K3: Hilfszeile | M3: =L3+3 -> 3 | N3: =M3+3 -> 6 | O3: =N3+3 -> 9 | P3: =O3+3 -> 12 | Q3: =P3+3 -> 15 | R3: =Q3+3 -> 18
B4: Parameter | C4: Value | D4: Unit | K4: Use phase | L4: {=OFFSET(Resume_SensAnal!$D$6,,L3,,)} -> NaNMC | M4: {=OFFSET(Resume_SensAnal!$D$6,,M3,,)} -> NaMVP | N4: {=OFFSET(Resume_SensAnal!$D$6,,N3,,)} -> NaMMO | O4: {=OFFSET(Resume_SensAnal!$D$6,,O3,,)} -> NaNMMT | P4: {=OFFSET(Resume_SensAnal!$D$6,,P3,,)} -> NaPBA | Q4: {=OFFSET(Resume_SensAnal!$D$6,,Q3,,)} -> LiNMC | R4: {=OFFSET(Resume_SensAnal!$D$6,,R3,,)} -> LiFP
B5: Capacity | C5: 2000 | D5: kWh | K5: Efficiency | L5: ='Use Phase'!L5 -> 0.92 | M5: ='Use Phase'!M5 -> 0.93 | N5: ='Use Phase'!N5 -> 0.92 | O5: ='Use Phase'!O5 -> 0.92 | P5: ='Use Phase'!P5 -> 0.93 | Q5: ='Use Phase'!Q5 -> 0.92 | R5: ='Use Phase'!R5 -> 0.93
B6: Power | C6: 1 | D6: MW | K6: Min SOC | L6: ='Use Phase'!L6 -> 0.2 | M6: ='Use Phase'!M6 -> 0.2 | N6: ='Use Phase'!N6 -> 0.2 | O6: ='Use Phase'!O6 -> 0.2 | P6: ='Use Phase'!P6 -> 0.2 | Q6: ='Use Phase'!Q6 -> 0.2 | R6: ='Use Phase'!R6 -> 0.2
B7: Cycles per day | C7: 2 | D7: - | K7: Max SOC | L7: ='Use Phase'!L7 -> 0.95 | M7: ='Use Phase'!M7 -> 0.95 | N7: ='Use Phase'!N7 -> 0.95 | O7: ='Use Phase'!O7 -> 0.95 | P7: ='Use Phase'!P7 -> 0.95 | Q7: ='Use Phase'!Q7 -> 0.95 | R7: ='Use Phase'!R7 -> 0.95
B8: Project life time | C8: 20 | D8: years | K8: Cycle life time | L8: ='Use Phase'!L8 -> 4000 | M8: ='Use Phase'!M8 -> 7000 | N8: ='Use Phase'!N8 -> 4000 | O8: ='Use Phase'!O8 -> 4000 | P8: ='Use Phase'!P8 -> 7000 | Q8: ='Use Phase'!Q8 -> 4000 | R8: ='Use Phase'!R8 -> 7000
B9: Cycles over project lifetime | C9: =C7*C8*365 -> 14600 | D9: Cylces | K9: Calendric Life time | L9: ='Use Phase'!L9 -> 10 | M9: ='Use Phase'!M9 -> 10 | N9: ='Use Phase'!N9 -> 10 | O9: ='Use Phase'!O9 -> 10 | P9: ='Use Phase'!P9 -> 10 | Q9: ='Use Phase'!Q9 -> 10 | R9: ='Use Phase'!R9 -> 10
K10: Retention rate | L10: ='Use Phase'!L10 -> 0.8 | M10: ='Use Phase'!M10 -> 0.8 | N10: ='Use Phase'!N10 -> 0.8 | O10: ='Use Phase'!O10 -> 0.8 | P10: ='Use Phase'!P10 -> 0.8 | Q10: ='Use Phase'!Q10 -> 0.8 | R10: ='Use Phase'!R10 -> 0.8
K11: Cap for 1 kWh provided | L11: ='Use Phase'!L11 -> 1.576087 | M11: ='Use Phase'!M11 -> 1.5591398 | N11: ='Use Phase'!N11 -> 1.576087 | O11: ='Use Phase'!O11 -> 1.576087 | P11: ='Use Phase'!P11 -> 1.5591398 | Q11: ='Use Phase'!Q11 -> 1.576087 | R11: ='Use Phase'!R11 -> 1.5591398
K12: Energy Density | L12: ='Use Phase'!L12 -> 136.31 | M12: ='Use Phase'!M12 -> 152.46717 | N12: ='Use Phase'!N12 -> 157.08 | O12: ='Use Phase'!O12 -> 171.91013 | P12: ='Use Phase'!P12 -> 124.1 | Q12: ='Use Phase'!Q12 -> 272.11478 | R12: ='Use Phase'!R12 -> 197.41872
B14: Total energy stored | C14: =C9*C6*C5 -> 29200000 | D14: kWh | K14: Factor | L14: =$L$5*C$19 -> 0 | M14: =$L$5*D$19 -> 0 | N14: =$L$5*E$19 -> 0 | O14: =$L$5*F$19 -> 0
B15: Total cycles per year | C15: =C14/20/(C6*1000) -> 1460 | D15: typical storage times --> 1000 - 2000 hours p.a. | K15: Total cap | L15: =L11*$C$5 -> 3152.1739 | M15: =M11*$C$5 -> 3118.2796 | N15: =N11*$C$5 -> 3152.1739 | O15: =O11*$C$5 -> 3152.1739 | P15: =P11*$C$5 -> 3118.2796 | Q15: =Q11*$C$5 -> 3152.1739 | R15: =R11*$C$5 -> 3118.2796
B16: Operation rate p. year | C16: =C15/8760 -> 0.16666667 | K16: Ex. Cell cycle | L16: =$C$9/L$8-1 -> 2.65 | M16: =$C$9/M$8-1 -> 1.0857143 | N16: =$C$9/N$8-1 -> 2.65 | O16: =$C$9/O$8-1 -> 2.65 | P16: =$C$9/P$8-1 -> 1.0857143 | Q16: =$C$9/Q$8-1 -> 2.65 | R16: =$C$9/R$8-1 -> 1.0857143
K17: Ex Cell cal. | L17: =$C$8/L$9-1 -> 1 | M17: =$C$8/M$9-1 -> 1 | N17: =$C$8/N$9-1 -> 1 | O17: =$C$8/O$9-1 -> 1 | P17: =$C$8/P$9-1 -> 1 | Q17: =$C$8/Q$9-1 -> 1 | R17: =$C$8/R$9-1 -> 1
K18: Used Ex | L18: =MAX(L16:L17) -> 2.65 | M18: =MAX(M16:M17) -> 1.0857143 | N18: =MAX(N16:N17) -> 2.65 | O18: =MAX(O16:O17) -> 2.65 | P18: =MAX(P16:P17) -> 1.0857143 | Q18: =MAX(Q16:Q17) -> 2.65 | R18: =MAX(R16:R17) -> 1.0857143
K19: Total consumed Energy | L19: =($C$14/L$5)-$C$14 -> 2539130.4 | M19: =($C$14/M$5)-$C$14 -> 2197849.5 | N19: =($C$14/N$5)-$C$14 -> 2539130.4 | O19: =($C$14/O$5)-$C$14 -> 2539130.4 | P19: =($C$14/P$5)-$C$14 -> 2197849.5 | Q19: =($C$14/Q$5)-$C$14 -> 2539130.4 | R19: =($C$14/R$5)-$C$14 -> 2197849.5
B20: Selected eletricity | C20: 1 | D20: 1 für electricty "from Grid", 2 für Wind, 3 für PV, 0 ohne Strom | K20: In % | L20: =L19/$C$14 -> 0.086956522 | M20: =M19/$C$14 -> 0.075268817 | N20: =N19/$C$14 -> 0.086956522 | O20: =O19/$C$14 -> 0.086956522 | P20: =P19/$C$14 -> 0.075268817 | Q20: =Q19/$C$14 -> 0.086956522 | R20: =R19/$C$14 -> 0.075268817
B21: AP | C21: =IF($C$20=1,D36,IF($C$20=2,D44,IF($C$20=3,D55,1E-68))) -> 0.00222
B22: GWP | C22: =IF($C$20=1,D37,IF($C$20=2,D45,IF($C$20=3,D56,1E-68))) -> 0.43101 | K22: Impacts per kg | L22: =L$4 -> NaNMC | M22: =M$4 -> NaMVP | N22: =N$4 -> NaMMO | O22: =O$4 -> NaNMMT | P22: =P$4 -> NaPBA | Q22: =Q$4 -> LiNMC | R22: =R$4 -> LiFP
B23: Htox | C23: =IF($C$20=1,D38,IF($C$20=2,D46,IF($C$20=3,D57,1E-68))) -> 0.0001742911 | K23: AP | L23: ='Use Phase'!L23 -> 0.37241611 | M23: ='Use Phase'!M23 -> 0.64029278 | N23: ='Use Phase'!N23 -> 0.20683414 | O23: ='Use Phase'!O23 -> 0.1940129 | P23: ='Use Phase'!P23 -> 0.29160133 | Q23: ='Use Phase'!Q23 -> 0.15050337 | R23: ='Use Phase'!R23 -> 0.21918138 | S23: molc H+ eq
B24: RDP | C24: =IF($C$20=1,D39,IF($C$20=2,D47,IF($C$20=3,D58,1E-68))) -> 3.25116e-06 | K24: GWP | L24: ='Use Phase'!L24 -> 54.753442 | M24: ='Use Phase'!M24 -> 81.329677 | N24: ='Use Phase'!N24 -> 45.995894 | O24: ='Use Phase'!O24 -> 37.25988 | P24: ='Use Phase'!P24 -> 73.93759 | Q24: ='Use Phase'!Q24 -> 27.419569 | R24: ='Use Phase'!R24 -> 43.045629 | S24: kg CO2 eq
B25: ODP | C25: =IF($C$20=1,D40,IF($C$20=2,D48,IF($C$20=3,D59,1E-68))) -> 1.79507e-08 | K25: Htox | L25: ='Use Phase'!L25 -> 0.036492357 | M25: ='Use Phase'!M25 -> 0.1700391 | N25: ='Use Phase'!N25 -> 0.014391044 | O25: ='Use Phase'!O25 -> 0.014249572 | P25: ='Use Phase'!P25 -> 0.019367221 | Q25: ='Use Phase'!Q25 -> 0.019079852 | R25: ='Use Phase'!R25 -> 0.026197194 | S25: kCTUh
B26: PMF | C26: =IF($C$20=1,D41,IF($C$20=2,D49,IF($C$20=3,D60,1E-68))) -> 0.00016 | K26: RDP | L26: ='Use Phase'!L26 -> 0.0079586888 | M26: ='Use Phase'!M26 -> 0.0039123043 | N26: ='Use Phase'!N26 -> 0.0014530193 | O26: ='Use Phase'!O26 -> 0.0029663651 | P26: ='Use Phase'!P26 -> 0.0021325974 | Q26: ='Use Phase'!Q26 -> 0.0017038118 | R26: ='Use Phase'!R26 -> 0.0058228955 | S26: kg Sb eq
K27: ODP | L27: ='Use Phase'!L27 -> 7.5256225e-06 | M27: ='Use Phase'!M27 -> 7.1322697e-06 | N27: ='Use Phase'!N27 -> 3.721214e-06 | O27: ='Use Phase'!O27 -> 3.3303444e-06 | P27: ='Use Phase'!P27 -> 8.1494825e-06 | Q27: ='Use Phase'!Q27 -> 3.0984322e-06 | R27: ='Use Phase'!R27 -> 3.6196093e-06 | S27: kg CFC-11 eq
K28: PMF | L28: ='Use Phase'!L28 -> 0.029624008 | M28: ='Use Phase'!M28 -> 0.051869583 | N28: ='Use Phase'!N28 -> 0.025459425 | O28: ='Use Phase'!O28 -> 0.014705597 | P28: ='Use Phase'!P28 -> 0.02634385 | Q28: ='Use Phase'!Q28 -> 0.013441182 | R28: ='Use Phase'!R28 -> 0.019747211 | S28: kg PM2.5 eq
K30: Impact per kWh | L30: =L$4 -> NaNMC | M30: =M$4 -> NaMVP | N30: =N$4 -> NaMMO | O30: =O$4 -> NaNMMT | P30: =P$4 -> NaPBA | Q30: =Q$4 -> LiNMC | R30: =R$4 -> LiFP
K31: AP | L31: =L23 -> 0.37241611 | M31: =M23 -> 0.64029278 | N31: =N23 -> 0.20683414 | O31: =O23 -> 0.1940129 | P31: =P23 -> 0.29160133 | Q31: =Q23 -> 0.15050337 | R31: =R23 -> 0.21918138 | S31: molc H+ eq
K32: GWP | L32: =L24 -> 54.753442 | M32: =M24 -> 81.329677 | N32: =N24 -> 45.995894 | O32: =O24 -> 37.25988 | P32: =P24 -> 73.93759 | Q32: =Q24 -> 27.419569 | R32: =R24 -> 43.045629 | S32: kg CO2 eq
K33: Htox | L33: =L25 -> 0.036492357 | M33: =M25 -> 0.1700391 | N33: =N25 -> 0.014391044 | O33: =O25 -> 0.014249572 | P33: =P25 -> 0.019367221 | Q33: =Q25 -> 0.019079852 | R33: =R25 -> 0.026197194 | S33: kCTUh
